<?xml version="1.0"?>

<robot
  name="pigeon_12">
  <link
    name="torso">
    <inertial>
      <origin
        xyz="-0.112665330319483 0 -0.0314957372746431"
        rpy="0 0 0" />
      <mass
        value="0.337792399438775" />
      <inertia
        ixx="0.000213744392058215"
        ixy="1.41607132067414E-08"
        ixz="4.48887348152591E-05"
        iyy="0.000899256138619334"
        iyz="-2.26830147050322E-09"
        izz="0.000883233595019567" />
    </inertial>
    <visual>
      <origin
        xyz="0 0 0"
        rpy="0 0 0" />
      <geometry>
        <mesh
          filename="../meshes/torso.STL" />
      </geometry>
      <material
        name="">
        <color
          rgba="0.5 0.5 0.5 1" />
      </material>
    </visual>
  </link>
  <link
    name="tail_pitch_ghost">
    <inertial>
       <mass
        value="0" />
    </inertial>
  </link>
  <joint
    name="tail_pitch"
    type="continuous">
    <origin
      xyz="-0.21 0 -0.0185680248036409"
      rpy="0 0 0" />
    <parent
      link="torso" />
    <child
      link="tail_pitch_ghost" />
    <axis
      xyz="0 -1 0" />
    <dynamics
      damping="0.0007" />
  </joint>
  <link
    name="tail">
    <inertial>
      <origin
        xyz="-0.0604601258312874 0 0"
        rpy="0 0 0" />
      <mass
        value="0.0036249709593909" />
      <inertia
        ixx="1.00703915425342E-05"
        ixy="1.02396207885307E-12"
        ixz="-6.90211316221857E-15"
        iyy="3.96754056530454E-06"
        iyz="-1.4818979967976E-12"
        izz="1.39841601392939E-05" />
    </inertial>
    <visual>
      <origin
        xyz="0 0 0"
        rpy="0 0 0" />
      <geometry>
        <mesh
          filename="../meshes/tail.STL" />
      </geometry>
      <material
        name="">
        <color
          rgba="0.5 0.5 0.5 1" />
      </material>
    </visual>
  </link>
  <joint
    name="tail_yaw"
    type="continuous">
    <origin
      xyz="0 0 0"
      rpy="0 0 0" />
    <parent
      link="tail_pitch_ghost" />
    <child
      link="tail" />
    <axis
      xyz="0 0 -1" />
    <dynamics
      damping="0.0007" />
  </joint>
  <link
    name="left_shoulder_roll_ghost">
    <inertial>
       <mass
        value="0" />
    </inertial>
  </link>
  <joint
    name="left_shoulder_roll"
    type="continuous">
    <origin
      xyz="-0.08 0.0223499999999991 -0.018568024803642"
      rpy="0 0 0" />
    <parent
      link="torso" />
    <child
      link="left_shoulder_roll_ghost" />
    <axis
      xyz="-1 0 0" />
    <dynamics
      damping="0.001" />
  </joint>
  <link
    name="left_shoulder_pitch_ghost">
    <inertial>
       <mass
        value="0" />
    </inertial>
  </link>
  <joint
    name="left_shoulder_pitch"
    type="continuous">
    <origin
      xyz="0 0 0"
      rpy="0 0 0" />
    <parent
      link="left_shoulder_roll_ghost" />
    <child
      link="left_shoulder_pitch_ghost" />
    <axis
      xyz="0 -1 0" />
    <dynamics
      damping="0.001" />
  </joint>
  <link
    name="left_upper_wing">
    <inertial>
      <origin
        xyz="-0.0589528659250431 -0.0175535746761525 0"
        rpy="0 0 0" />
      <mass
        value="0.0061260000339972" />
      <inertia
        ixx="6.98406752630041E-07"
        ixy="-1.27189358154334E-07"
        ixz="2.31675839223798E-12"
        iyy="8.88423587527098E-06"
        iyz="2.73194876697933E-13"
        izz="9.39762886356504E-06" />
    </inertial>
    <visual>
      <origin
        xyz="0 0 0"
        rpy="0 0 0" />
      <geometry>
        <mesh
          filename="../meshes/left_upper_wing.STL" />
      </geometry>
      <material
        name="">
        <color
          rgba="0.5 0.5 0.5 1" />
      </material>
    </visual>
  </link>
  <joint
    name="left_shoulder_yaw"
    type="continuous">
    <origin
      xyz="0 0 0"
      rpy="3.14159265358979 0 0" />
    <parent
      link="left_shoulder_pitch_ghost" />
    <child
      link="left_upper_wing" />
    <axis
      xyz="0 0 -1" />
    <dynamics
      damping="0.001" />
  </joint>
  <link
    name="left_mid_wing">
    <inertial>
      <origin
        xyz="-0.0309238874102576 -0.0478670898967761 0"
        rpy="0 0 0" />
      <mass
        value="0.0118435988338924" />
      <inertia
        ixx="1.30936667015947E-05"
        ixy="3.30210259795646E-06"
        ixz="1.63589982933577E-13"
        iyy="1.60328428980403E-05"
        iyz="-1.13526713077698E-11"
        izz="2.88763216840841E-05" />
    </inertial>
    <visual>
      <origin
        xyz="0 0 0"
        rpy="0 0 0" />
      <geometry>
        <mesh
          filename="../meshes/left_mid_wing.STL" />
      </geometry>
      <material
        name="">
        <color
          rgba="0.5 0.5 0.5 1" />
      </material>
    </visual>
  </link>
  <joint
    name="left_elbow_yaw"
    type="continuous">
    <origin
      xyz="-0.0249799919935938 -0.0350000000000007 0"
      rpy="0 0 0" />
    <parent
      link="left_upper_wing" />
    <child
      link="left_mid_wing" />
    <axis
      xyz="0 0 -1" />
    <dynamics
      damping="0.001" />
  </joint>
  <link
    name="left_wrist_roll_ghost">
    <inertial>
       <mass
        value="0" />
    </inertial>
  </link>
  <joint
    name="left_wrist_roll"
    type="continuous">
    <origin
      xyz="0.0519142912418165 -0.0349999999999929 0"
      rpy="0 0 0" />
    <parent
      link="left_mid_wing" />
    <child
      link="left_wrist_roll_ghost" />
    <axis
      xyz="-1 0 0" />
    <dynamics
      damping="0.0007" />
  </joint>
  <link
    name="left_wrist_pitch_ghost">
    <inertial>
       <mass
        value="0" />
    </inertial>
  </link>
  <joint
    name="left_wrist_pitch"
    type="continuous">
    <origin
      xyz="0 0 0"
      rpy="0 0 0" />
    <parent
      link="left_wrist_roll_ghost" />
    <child
      link="left_wrist_pitch_ghost" />
    <axis
      xyz="0 -1 0" />
    <dynamics
      damping="0.0007" />
  </joint>
  <link
    name="left_hand_wing">
    <inertial>
      <origin
        xyz="-0.0496305425022118 -0.114426970261576 0"
        rpy="0 0 0" />
      <mass
        value="0.00775959953779964" />
      <inertia
        ixx="2.04444761571872E-05"
        ixy="5.05536086513179E-06"
        ixz="-5.9785908731589E-10"
        iyy="6.83432712985456E-06"
        iyz="-1.22871287545177E-09"
        izz="2.72012939551026E-05" />
    </inertial>
    <visual>
      <origin
        xyz="0 0 0"
        rpy="0 0 0" />
      <geometry>
        <mesh
          filename="../meshes/left_hand_wing.STL" />
      </geometry>
      <material
        name="">
        <color
          rgba="0.5 0.5 0.5 1" />
      </material>
    </visual>
  </link>
  <joint
    name="left_wrist_yaw"
    type="continuous">
    <origin
      xyz="0 0 0"
      rpy="0 0 0" />
    <parent
      link="left_wrist_pitch_ghost" />
    <child
      link="left_hand_wing" />
    <axis
      xyz="0 0 -1" />
    <dynamics
      damping="0.0007" />
  </joint>
  <link
    name="right_shoulder_roll_ghost">
    <inertial>
       <mass
        value="0" />
    </inertial>
  </link>
  <joint
    name="right_shoulder_roll"
    type="continuous">
    <origin
      xyz="-0.08 -0.02235 -0.0185680248036409"
      rpy="0 0 0" />
    <parent
      link="torso" />
    <child
      link="right_shoulder_roll_ghost" />
    <axis
      xyz="-1 0 0" />
    <dynamics
      damping="0.001" />
  </joint>
  <link
    name="right_shoulder_pitch_ghost">
    <inertial>
       <mass
        value="0" />
    </inertial>
  </link>
  <joint
    name="right_shoulder_pitch"
    type="continuous">
    <origin
      xyz="0 0 0"
      rpy="0 0 0" />
    <parent
      link="right_shoulder_roll_ghost" />
    <child
      link="right_shoulder_pitch_ghost" />
    <axis
      xyz="0 -1 0" />
    <dynamics
      damping="0.001" />
  </joint>
  <link
    name="right_upper_wing">
    <inertial>
      <origin
        xyz="-0.0589528659250257 -0.0175535746761505 0"
        rpy="0 0 0" />
      <mass
        value="0.00612600003399489" />
      <inertia
        ixx="6.98406752630195E-07"
        ixy="-1.27189358155062E-07"
        ixz="2.3167583496552E-12"
        iyy="8.88423587526525E-06"
        iyz="2.73194499900361E-13"
        izz="9.39762886355896E-06" />
    </inertial>
    <visual>
      <origin
        xyz="0 0 0"
        rpy="0 0 0" />
      <geometry>
        <mesh
          filename="../meshes/right_upper_wing.STL" />
      </geometry>
      <material
        name="">
        <color
          rgba="0.5 0.5 0.5 1" />
      </material>
    </visual>
  </link>
  <joint
    name="right_shoulder_yaw"
    type="continuous">
    <origin
      xyz="0 0 0"
      rpy="0 0 0" />
    <parent
      link="right_shoulder_pitch_ghost" />
    <child
      link="right_upper_wing" />
    <axis
      xyz="0 0 1" />
    <dynamics
      damping="0.001" />
  </joint>
  <link
    name="right_mid_wing">
    <inertial>
      <origin
        xyz="-0.0309238874102866 -0.0478670898968001 0"
        rpy="0 0 0" />
      <mass
        value="0.0118435988338867" />
      <inertia
        ixx="1.30936667016344E-05"
        ixy="3.30210259797076E-06"
        ixz="1.63583111239116E-13"
        iyy="1.60328428981203E-05"
        iyz="-1.13526918293286E-11"
        izz="2.88763216842037E-05" />
    </inertial>
    <visual>
      <origin
        xyz="0 0 0"
        rpy="0 0 0" />
      <geometry>
        <mesh
          filename="../meshes/right_mid_wing.STL" />
      </geometry>
      <material
        name="">
        <color
          rgba="0.5 0.5 0.5 1" />
      </material>
    </visual>
  </link>
  <joint
    name="right_elbow_yaw"
    type="continuous">
    <origin
      xyz="-0.0249799919935937 -0.0350000000000001 0"
      rpy="0 0 0" />
    <parent
      link="right_upper_wing" />
    <child
      link="right_mid_wing" />
    <axis
      xyz="0 0 -1" />
    <dynamics
      damping="0.001" />
  </joint>
  <link
    name="right_wrist_roll_ghost">
    <inertial>
       <mass
        value="0" />
    </inertial>
  </link>
  <joint
    name="right_wrist_roll"
    type="continuous">
    <origin
      xyz="0.0519142912418186 -0.034999999999993 0"
      rpy="0 0 0" />
    <parent
      link="right_mid_wing" />
    <child
      link="right_wrist_roll_ghost" />
    <axis
      xyz="-1 0 0" />
    <dynamics
      damping="0.0007" />
  </joint>
  <link
    name="right_wrist_pitch_ghost">
    <inertial>
       <mass
        value="0" />
    </inertial>
  </link>
  <joint
    name="right_wrist_pitch"
    type="continuous">
    <origin
      xyz="0 0 0"
      rpy="0 0 0" />
    <parent
      link="right_wrist_roll_ghost" />
    <child
      link="right_wrist_pitch_ghost" />
    <axis
      xyz="0 -1 0" />
    <dynamics
      damping="0.0007" />
  </joint>
  <link
    name="right_hand_wing">
    <inertial>
      <origin
        xyz="-0.0496305425022117 -0.114426970261576 0"
        rpy="0 0 0" />
      <mass
        value="0.00775959953779963" />
      <inertia
        ixx="2.04444761571871E-05"
        ixy="5.05536086513198E-06"
        ixz="-5.97859087319399E-10"
        iyy="6.83432712985444E-06"
        iyz="-1.22871287545199E-09"
        izz="2.72012939551023E-05" />
    </inertial>
    <visual>
      <origin
        xyz="0 0 0"
        rpy="0 0 0" />
      <geometry>
        <mesh
          filename="../meshes/right_hand_wing.STL" />
      </geometry>
      <material
        name="">
        <color
          rgba="0.5 0.5 0.5 1" />
      </material>
    </visual>
  </link>
  <joint
    name="right_wrist_yaw"
    type="continuous">
    <origin
      xyz="0 0 0"
      rpy="0 0 0" />
    <parent
      link="right_wrist_pitch_ghost" />
    <child
      link="right_hand_wing" />
    <axis
      xyz="0 0 -1" />
    <dynamics
      damping="0.0007" />
  </joint>

  <transmission name="tail_pitch_torque" type="SimpleTransmission" >
    <joint name="tail_pitch" />
    <actuator name="tail_pitch_servo"/>
    <mechanicalReduction>1</mechanicalReduction>
  </transmission>
  <transmission name="tail_yaw_torque" type="SimpleTransmission" >
    <joint name="tail_yaw" />
    <actuator name="tail_yaw_servo"/>
    <mechanicalReduction>1</mechanicalReduction>
  </transmission>
  <transmission name="left_shoulder_roll_torque" type="SimpleTransmission" >
    <joint name="left_shoulder_roll" />
    <actuator name="left_shoulder_roll_servo"/>
    <mechanicalReduction>1</mechanicalReduction>
  </transmission>
  <transmission name="left_shoulder_pitch_torque" type="SimpleTransmission" >
    <joint name="left_shoulder_pitch" />
    <actuator name="left_shoulder_pitch_servo"/>
    <mechanicalReduction>1</mechanicalReduction>
  </transmission>
  <transmission name="left_shoulder_yaw_torque" type="SimpleTransmission" >
    <joint name="left_shoulder_yaw" />
    <actuator name="left_shoulder_yaw_servo"/>
    <mechanicalReduction>1</mechanicalReduction>
  </transmission>
  <transmission name="left_elbow_yaw_torque" type="SimpleTransmission" >
    <joint name="left_elbow_yaw" />
    <actuator name="left_elbow_yaw_servo"/>
    <mechanicalReduction>1</mechanicalReduction>
  </transmission>
  <transmission name="left_wrist_roll_torque" type="SimpleTransmission" >
    <joint name="left_wrist_roll" />
    <actuator name="left_wrist_roll_servo"/>
    <mechanicalReduction>1</mechanicalReduction>
  </transmission>
  <transmission name="left_wrist_pitch_torque" type="SimpleTransmission" >
    <joint name="left_wrist_pitch" />
    <actuator name="left_wrist_pitch_servo"/>
    <mechanicalReduction>1</mechanicalReduction>
  </transmission>
  <transmission name="left_wrist_yaw_torque" type="SimpleTransmission" >
    <joint name="left_wrist_yaw" />
    <actuator name="left_wrist_yaw_servo"/>
    <mechanicalReduction>1</mechanicalReduction>
  </transmission>
  <transmission name="right_shoulder_roll_torque" type="SimpleTransmission" >
    <joint name="right_shoulder_roll" />
    <actuator name="right_shoulder_roll_servo"/>
    <mechanicalReduction>1</mechanicalReduction>
  </transmission>
  <transmission name="right_shoulder_pitch_torque" type="SimpleTransmission" >
    <joint name="right_shoulder_pitch" />
    <actuator name="right_shoulder_pitch_servo"/>
    <mechanicalReduction>1</mechanicalReduction>
  </transmission>
  <transmission name="right_shoulder_yaw_torque" type="SimpleTransmission" >
    <joint name="right_shoulder_yaw" />
    <actuator name="right_shoulder_yaw_servo"/>
    <mechanicalReduction>1</mechanicalReduction>
  </transmission>
  <transmission name="right_elbow_yaw_torque" type="SimpleTransmission" >
    <joint name="right_elbow_yaw" />
    <actuator name="right_elbow_yaw_servo"/>
    <mechanicalReduction>1</mechanicalReduction>
  </transmission>
  <transmission name="right_wrist_roll_torque" type="SimpleTransmission" >
    <joint name="right_wrist_roll" />
    <actuator name="right_wrist_roll_servo"/>
    <mechanicalReduction>1</mechanicalReduction>
  </transmission>
  <transmission name="right_wrist_pitch_torque" type="SimpleTransmission" >
    <joint name="right_wrist_pitch" />
    <actuator name="right_wrist_pitch_servo"/>
    <mechanicalReduction>1</mechanicalReduction>
  </transmission>
  <transmission name="right_wrist_yaw_torque" type="SimpleTransmission" >
    <joint name="right_wrist_yaw" />
    <actuator name="right_wrist_yaw_servo"/>
    <mechanicalReduction>1</mechanicalReduction>
  </transmission>

  <force_element name="tail_force"> 
    <wing chord=".14074" nominal_speed="1" profile="flat plate" span=".25727" stall_angle="181">
      <parent link="tail"/>
  	<origin xyz="0 0 0" rpy="0 0 0"/> 
    </wing>
  </force_element>
<!--  <force_element name="left_upper_wing_force"> 
    <wing chord=".13969" nominal_speed="1" profile="flat plate" span=".03500" stall_angle="181">
      <parent link="left_upper_wing"/>
  	<origin xyz="0 0 0" rpy="0 0 0"/>
    </wing> -->
  <force_element name="left_mid_wing_force"> 
    <wing chord=".15160" nominal_speed="1" profile="flat plate" span=".14611" stall_angle="181">
      <parent link="left_mid_wing"/>
  	<origin xyz="0 0 0" rpy="0 0 0"/> 
    </wing>
  </force_element>
  <force_element name="left_hand_wing_force"> 
    <wing chord=".11713" nominal_speed="1" profile="flat plate" span=".23045" stall_angle="181">
      <parent link="left_hand_wing"/>
  	<origin xyz="0 0 0" rpy="0 0 0"/> 
    </wing>
  </force_element>
<!--  <force_element name="right_upper_wing_force"> 
    <wing chord=".13969" nominal_speed="1" profile="flat plate" span=".03500" stall_angle="181">
      <parent link="right_upper_wing"/>
  	<origin xyz="0 0 0" rpy="0 0 0"/>
    </wing> -->
  <force_element name="right_mid_wing_force"> 
    <wing chord=".15160" nominal_speed="1" profile="flat plate" span=".14611" stall_angle="181">
      <parent link="right_mid_wing"/>
  	<origin xyz="0 0 0" rpy="0 0 0"/> 
    </wing>
  </force_element>
  <force_element name="right_hand_wing_force">
    <wing chord=".11713" nominal_speed="1" profile="flat plate" span=".23045" stall_angle="181">
      <parent link="right_hand_wing"/>
  	<origin xyz="0 0 0" rpy="0 0 0"/> 
    </wing> 
  </force_element>
  <force_element name="tail_pitch_spring">
    <torsional_spring stiffness="0.005" rest_angle="0">
      <joint name="tail_pitch" />
    </torsional_spring>
  </force_element>
  <force_element name="tail_yaw_spring">
    <torsional_spring stiffness="0.005" rest_angle="0">
      <joint name="tail_yaw" />
    </torsional_spring>
  </force_element>
  <force_element name="left_shoulder_roll_spring">
    <torsional_spring stiffness="0.1" rest_angle="0">
      <joint name="left_shoulder_roll" />
    </torsional_spring>
  </force_element>
  <force_element name="left_shoulder_pitch_spring">
    <torsional_spring stiffness="0.1" rest_angle="0">
      <joint name="left_shoulder_pitch" />
    </torsional_spring>
  </force_element>
  <force_element name="left_shoulder_yaw_spring">
    <torsional_spring stiffness="0.1" rest_angle="0">
      <joint name="left_shoulder_yaw" />
    </torsional_spring>
  </force_element>
  <force_element name="left_elbow_yaw_spring">
    <torsional_spring stiffness="0.05" rest_angle="0">
      <joint name="left_elbow_yaw" />
    </torsional_spring>
  </force_element>
  <force_element name="left_wrist_roll_spring">
    <torsional_spring stiffness="0.005" rest_angle="0">
      <joint name="left_wrist_roll" />
    </torsional_spring>
  </force_element>
  <force_element name="left_wrist_pitch_spring">
    <torsional_spring stiffness="0.005" rest_angle="0">
      <joint name="left_wrist_pitch" />
    </torsional_spring>
  </force_element>
  <force_element name="left_wrist_yaw_spring">
    <torsional_spring stiffness="0.005" rest_angle="0">
      <joint name="left_wrist_yaw" />
    </torsional_spring>
  </force_element>
  <force_element name="right_shoulder_roll_spring">
    <torsional_spring stiffness="0.1" rest_angle="0">
      <joint name="right_shoulder_roll" />
    </torsional_spring>
  </force_element>
  <force_element name="right_shoulder_pitch_spring">
    <torsional_spring stiffness="0.1" rest_angle="0">
      <joint name="right_shoulder_pitch" />
    </torsional_spring>
  </force_element>
  <force_element name="right_shoulder_yaw_spring">
    <torsional_spring stiffness="0.1" rest_angle="0">
      <joint name="right_shoulder_yaw" />
    </torsional_spring>
  </force_element>
  <force_element name="right_elbow_yaw_spring">
    <torsional_spring stiffness="0.05" rest_angle="0">
      <joint name="right_elbow_yaw" />
    </torsional_spring>
  </force_element>
  <force_element name="right_wrist_roll_spring">
    <torsional_spring stiffness="0.005" rest_angle="0">
      <joint name="right_wrist_roll" />
    </torsional_spring>
  </force_element>
  <force_element name="right_wrist_pitch_spring">
    <torsional_spring stiffness="0.005" rest_angle="0">
      <joint name="right_wrist_pitch" />
    </torsional_spring>
  </force_element>
  <force_element name="right_wrist_yaw_spring">
    <torsional_spring stiffness="0.005" rest_angle="0">
      <joint name="right_wrist_yaw" />
    </torsional_spring>
  </force_element>

</robot>
