<?xml version="1.0"?>

<robot
  name="pigeon_6">
  <link
    name="torso">
    <inertial>
      <origin
        xyz="-0.132434070149677 -0.00712750625005471 2.92945297023312E-07"
        rpy="0 0 0" />
      <mass
        value="0.266575552840038" />
      <inertia
        ixx="0.00016350796386525"
        ixy="1.49468441773124E-05"
        ixz="1.32757604674385E-08"
        iyy="0.0008571776199688"
        iyz="8.6217450863791E-09"
        izz="0.000802843103287114" />
    </inertial>
    <visual>
      <origin
        xyz="0 0 0"
        rpy="0 0 0" />
      <geometry>
        <mesh
          filename="../meshes/torso.STL" />
      </geometry>
      <material
        name="">
        <color
          rgba="0.5 0.5 0.5 1" />
      </material>
    </visual>
  </link>
  <link
    name="tail">
    <inertial>
      <origin
        xyz="-1.02999651663334E-15 -3.40754664632007E-18 -0.0652517307094301"
        rpy="0 0 0" />
      <mass
        value="0.00283414865838335" />
      <inertia
        ixx="2.346394244564E-06"
        ixy="1.49306100565822E-23"
        ixz="-2.40286154217874E-20"
        iyy="1.14735911790603E-05"
        iyz="7.77840767722693E-24"
        izz="9.13466619052064E-06" />
    </inertial>
    <visual>
      <origin
        xyz="0 0 0"
        rpy="0 0 0" />
      <geometry>
        <mesh
          filename="../meshes/tail.STL" />
      </geometry>
      <material
        name="">
        <color
          rgba="0.5 0.5 0.5 1" />
      </material>
    </visual>
  </link>
  <joint
    name="tail_joint"
    type="continuous">
    <origin
      xyz="-0.229979541052234 0 0"
      rpy="-1.5707963267949 -6.12303176911189E-17 -1.5707963267949" />
    <parent
      link="torso" />
    <child
      link="tail" />
    <axis
      xyz="-1 0 0" />
    <dynamics
      damping="0.0007" />
  </joint>
  <transmission name="tail_joint_torque" type="SimpleTransmission" >
    <joint name="tail_joint" />
    <actuator name="tail_joint_servo"/>
    <mechanicalReduction>1</mechanicalReduction>
  </transmission>
  <link
    name="left_shoulder_roll_ghost">
     <inertial>
        <mass
         value="0" />
     </inertial>
  </link>
  <joint
    name="left_shoulder_roll"
    type="continuous">
    <origin
      xyz="-0.07698 0.042 0"
      rpy="1.5708 0 0" />
    <parent
      link="torso" />
    <child
      link="left_shoulder_roll_ghost" />
    <axis
      xyz="-1 0 0" />
    <dynamics
      damping="0.001" />
  </joint>
  <transmission name="left_shoulder_roll_torque" type="SimpleTransmission" >
    <joint name="left_shoulder_roll" />
    <actuator name="left_shoulder_roll_servo"/>
    <mechanicalReduction>1</mechanicalReduction>
  </transmission>
  <link
    name="left_shoulder_pitch_ghost">
     <inertial>
        <mass
         value="0" />
     </inertial>
  </link>
  <joint
    name="left_shoulder_pitch"
    type="continuous">
    <origin
      xyz="-0.005 0 0"
      rpy="0 0 3.141592653" />
    <parent
      link="left_shoulder_roll_ghost" />
    <child
      link="left_shoulder_pitch_ghost" />
    <axis
      xyz="0 0 -1" />
    <dynamics
      damping="0.001" />
  </joint>
  <transmission name="left_shoulder_pitch_torque" type="SimpleTransmission" >
    <joint name="left_shoulder_pitch" />
    <actuator name="left_shoulder_pitch_servo"/>
    <mechanicalReduction>1</mechanicalReduction>
  </transmission>
  <link
    name="left_upper_wing">
    <inertial>
      <origin
        xyz="-0.0218027728742865 1.26519788753939E-08 -0.0593039239207447"
        rpy="0 0 0" />
      <mass
        value="0.00478467934314602" />
      <inertia
        ixx="3.47747506697265E-06"
        ixy="1.4332659850445E-12"
        ixz="4.41899816252948E-07"
        iyy="4.15090260308389E-06"
        iyz="-3.28097162561639E-12"
        izz="6.85803263309495E-07" />
    </inertial>
    <visual>
      <origin
        xyz="0 0 0"
        rpy="0 0 0" />
      <geometry>
        <mesh
          filename="../meshes/left_upper_wing.STL" />
      </geometry>
      <material
        name="">
        <color
          rgba="0.5 0.5 0.5 1" />
      </material>
    </visual>
  </link>
  <joint
    name="left_shoulder_yaw"
    type="continuous">
    <origin
      xyz="0.005 0 0"
      rpy="0 -1.5708 0" />
    <parent
      link="left_shoulder_pitch_ghost" />
    <child
      link="left_upper_wing" />
    <axis
      xyz="0 1 0" />
    <dynamics
      damping="0.001" />
  </joint>
  <transmission name="left_shoulder_yaw_torque" type="SimpleTransmission" >
    <joint name="left_shoulder_yaw" />
    <actuator name="left_shoulder_yaw_servo"/>
    <mechanicalReduction>1</mechanicalReduction>
  </transmission>
  <link
    name="left_elbow_roll_ghost">
     <inertial>
        <mass
         value="0" />
     </inertial>
  </link>
  <joint
    name="left_elbow_roll"
    type="continuous">
    <origin
      xyz="-0.041998 0 -0.015054"
      rpy="0 -1.5708 0" />
    <parent
      link="left_upper_wing" />
    <child
      link="left_elbow_roll_ghost" />
    <axis
      xyz="-1 0 0" />
    <dynamics
      damping="0.001" />
  </joint>
  <transmission name="left_elbow_roll_torque" type="SimpleTransmission" >
    <joint name="left_elbow_roll" />
    <actuator name="left_elbow_roll_servo"/>
    <mechanicalReduction>1</mechanicalReduction>
  </transmission>
  <link
    name="left_elbow_pitch_ghost">
     <inertial>
        <mass
         value="0" />
     </inertial>
  </link>
  <joint
    name="left_elbow_pitch"
    type="continuous">
    <origin
      xyz="-0.005 0 0"
      rpy="0 0 0" />
    <parent
      link="left_elbow_roll_ghost" />
    <child
      link="left_elbow_pitch_ghost" />
    <axis
      xyz="0 0 -1" />
    <dynamics
      damping="0.001" />
  </joint>
  <transmission name="left_elbow_pitch_torque" type="SimpleTransmission" >
    <joint name="left_elbow_pitch" />
    <actuator name="left_elbow_pitch_servo"/>
    <mechanicalReduction>1</mechanicalReduction>
  </transmission>
  <link
    name="left_mid_wing">
    <inertial>
      <origin
        xyz="-0.0461463515315643 -7.03928821877167E-08 -0.0495486671552648"
        rpy="0 0 0" />
      <mass
        value="0.0092322213928293" />
      <inertia
        ixx="1.13159761781576E-05"
        ixy="2.18214270652104E-11"
        ixz="-1.6520467139039E-06"
        iyy="1.76124962714535E-05"
        iyz="1.10157921371717E-12"
        izz="6.32076926607802E-06" />
    </inertial>
    <visual>
      <origin
        xyz="0 0 0"
        rpy="0 0 0" />
      <geometry>
        <mesh
          filename="../meshes/left_mid_wing.STL" />
      </geometry>
      <material
        name="">
        <color
          rgba="0.5 0.5 0.5 1" />
      </material>
    </visual>
  </link>
  <joint
    name="left_elbow_yaw"
    type="continuous">
    <origin
      xyz="0 0 0"
      rpy="0 1.5708 0" />
    <parent
      link="left_elbow_pitch_ghost" />
    <child
      link="left_mid_wing" />
    <axis
      xyz="0 1 0" />
    <dynamics
      damping="0.001" />
  </joint>
  <transmission name="left_elbow_yaw_torque" type="SimpleTransmission" >
    <joint name="left_elbow_yaw" />
    <actuator name="left_elbow_yaw_servo"/>
    <mechanicalReduction>1</mechanicalReduction>
  </transmission>
  <link
    name="left_hand_wing">
    <inertial>
      <origin
        xyz="-0.0597835058137273 -3.75375056547601E-08 -0.0458134569307157"
        rpy="0 0 0" />
      <mass
        value="0.00605546079567201" />
      <inertia
        ixx="4.30150583723145E-06"
        ixy="7.40776319597981E-12"
        ixz="1.56448026115006E-06"
        iyy="1.33027567122271E-05"
        iyz="4.65471379102572E-13"
        izz="9.01715501968073E-06" />
    </inertial>
    <visual>
      <origin
        xyz="0 0 0"
        rpy="0 0 0" />
      <geometry>
        <mesh
          filename="../meshes/left_hand_wing.STL" />
      </geometry>
      <material
        name="">
        <color
          rgba="0.5 0.5 0.5 1" />
      </material>
    </visual>
  </link>
  <joint
    name="left_wrist_roll"
    type="continuous">
    <origin
      xyz="-0.092963 0 0"
      rpy="0 0 1.1102E-14" />
    <parent
      link="left_mid_wing" />
    <child
      link="left_hand_wing" />
    <axis
      xyz="0 0 -1" />
    <dynamics
      damping="0.0007" />
  </joint>
  <transmission name="left_wrist_roll_torque" type="SimpleTransmission" >
    <joint name="left_wrist_roll" />
    <actuator name="left_wrist_roll_servo"/>
    <mechanicalReduction>1</mechanicalReduction>
  </transmission>
  <link
    name="right_shoulder_roll_ghost">
     <inertial>
        <mass
         value="0" />
     </inertial>
  </link>
  <joint
    name="right_shoulder_roll"
    type="continuous">
    <origin
      xyz="-0.076979541052234 -0.042 0"
      rpy="1.5707963267949 0 0" />
    <parent
      link="torso" />
    <child
      link="right_shoulder_roll_ghost" />
    <axis
      xyz="-1 0 0" />
    <dynamics
      damping="0.001" />
  </joint>
  <transmission name="right_shoulder_roll_torque" type="SimpleTransmission" >
    <joint name="right_shoulder_roll" />
    <actuator name="right_shoulder_roll_servo"/>
    <mechanicalReduction>1</mechanicalReduction>
  </transmission>
  <link
    name="right_shoulder_pitch_ghost">
     <inertial>
        <mass
         value="0" />
     </inertial>
  </link>
  <joint
    name="right_shoulder_pitch"
    type="continuous">
    <origin
      xyz="-0.005 0 0"
      rpy="0 0 0" />
    <parent
      link="right_shoulder_roll_ghost" />
    <child
      link="right_shoulder_pitch_ghost" />
    <axis
      xyz="0 0 -1" />
    <dynamics
      damping="0.001" />
  </joint>
  <transmission name="right_shoulder_pitch_torque" type="SimpleTransmission" >
    <joint name="right_shoulder_pitch" />
    <actuator name="right_shoulder_pitch_servo"/>
    <mechanicalReduction>1</mechanicalReduction>
  </transmission>
  <link
    name="right_upper_wing">
    <inertial>
      <origin
        xyz="-0.0218027728742856 -1.26519788395134E-08 0.0543039239207451"
        rpy="0 0 0" />
      <mass
        value="0.00478467934314603" />
      <inertia
        ixx="3.47747506697266E-06"
        ixy="-1.43326598006839E-12"
        ixz="-4.41899816252929E-07"
        iyy="4.15090260308389E-06"
        iyz="-3.28097162893791E-12"
        izz="6.8580326330949E-07" />
    </inertial>
    <visual>
      <origin
        xyz="0 0 0"
        rpy="0 0 0" />
      <geometry>
        <mesh
          filename="../meshes/right_upper_wing.STL" />
      </geometry>
      <material
        name="">
        <color
          rgba="0.5 0.5 0.5 1" />
      </material>
    </visual>
  </link>
  <joint
    name="right_shoulder_yaw"
    type="continuous">
    <origin
      xyz="0 0 0"
      rpy="3.1416 1.5708 0" />
    <parent
      link="right_shoulder_pitch_ghost" />
    <child
      link="right_upper_wing" />
    <axis
      xyz="0 1 0" />
    <dynamics
      damping="0.001" />
  </joint>
  <transmission name="right_shoulder_yaw_torque" type="SimpleTransmission" >
    <joint name="right_shoulder_yaw" />
    <actuator name="right_shoulder_yaw_servo"/>
    <mechanicalReduction>1</mechanicalReduction>
  </transmission>
  <link
    name="right_elbow_roll_ghost">
     <inertial>
        <mass
         value="0" />
     </inertial>
  </link>
  <joint
    name="right_elbow_roll"
    type="continuous">
    <origin
      xyz="-0.041998 0 0.010054"
      rpy="3.1416 1.5708 0" />
    <parent
      link="right_upper_wing" />
    <child
      link="right_elbow_roll_ghost" />
    <axis
      xyz="-1 0 0" />
    <dynamics
      damping="0.001" />
  </joint>
  <transmission name="right_elbow_roll_torque" type="SimpleTransmission" >
    <joint name="right_elbow_roll" />
    <actuator name="right_elbow_roll_servo"/>
    <mechanicalReduction>1</mechanicalReduction>
  </transmission>
  <link
    name="right_elbow_pitch_ghost">
     <inertial>
        <mass
         value="0" />
     </inertial>
  </link>
  <joint
    name="right_elbow_pitch"
    type="continuous">
    <origin
      xyz="-0.005 0 0"
      rpy="0 0 0" />
    <parent
      link="right_elbow_roll_ghost" />
    <child
      link="right_elbow_pitch_ghost" />
    <axis
      xyz="0 0 -1" />
    <dynamics
      damping="0.001" />
  </joint>
  <transmission name="right_elbow_pitch_torque" type="SimpleTransmission" >
    <joint name="right_elbow_pitch" />
    <actuator name="right_elbow_pitch_servo"/>
    <mechanicalReduction>1</mechanicalReduction>
  </transmission>
  <link
    name="right_mid_wing">
    <inertial>
      <origin
        xyz="-0.0461463515315641 7.03928823037418E-08 0.049548667155265"
        rpy="0 0 0" />
      <mass
        value="0.00923222139282929" />
      <inertia
        ixx="1.13159761781577E-05"
        ixy="-2.18214271520626E-11"
        ixz="1.65204671390387E-06"
        iyy="1.76124962714536E-05"
        iyz="1.10157919096275E-12"
        izz="6.32076926607806E-06" />
    </inertial>
    <visual>
      <origin
        xyz="0 0 0"
        rpy="0 0 0" />
      <geometry>
        <mesh
          filename="../meshes/right_mid_wing.STL" />
      </geometry>
      <material
        name="">
        <color
          rgba="0.5 0.5 0.5 1" />
      </material>
    </visual>
  </link>
  <joint
    name="right_elbow_yaw"
    type="continuous">
    <origin
      xyz="0 0 0"
      rpy="3.1416 1.5708 0" />
    <parent
      link="right_elbow_pitch_ghost" />
    <child
      link="right_mid_wing" />
    <axis
      xyz="0 1 0" />
    <dynamics
      damping="0.001" />
  </joint>
  <transmission name="right_elbow_yaw_torque" type="SimpleTransmission" >
    <joint name="right_elbow_yaw" />
    <actuator name="right_elbow_yaw_servo"/>
    <mechanicalReduction>1</mechanicalReduction>
  </transmission>
  <link
    name="right_hand_wing">
    <inertial>
      <origin
        xyz="-0.0597835058137272 3.75375041037705E-08 0.0458134569307162"
        rpy="0 0 0" />
      <mass
        value="0.00605546079567198" />
      <inertia
        ixx="4.30150583722961E-06"
        ixy="-7.40776313110685E-12"
        ixz="-1.56448026114958E-06"
        iyy="1.33027567122248E-05"
        iyz="4.65471368181661E-13"
        izz="9.01715501968028E-06" />
    </inertial>
    <visual>
      <origin
        xyz="0 0 0"
        rpy="0 0 0" />
      <geometry>
        <mesh
          filename="../meshes/right_hand_wing.STL" />
      </geometry>
      <material
        name="">
        <color
          rgba="0.5 0.5 0.5 1" />
      </material>
    </visual>
  </link>
  <joint
    name="right_wrist_roll"
    type="continuous">
    <origin
      xyz="-0.092963 0 0"
      rpy="0 0 -3.1919E-14" />
    <parent
      link="right_mid_wing" />
    <child
      link="right_hand_wing" />
    <axis
      xyz="0 0 1" />
    <dynamics
      damping="0.0007" />
  </joint>
  <transmission name="right_wrist_roll_torque" type="SimpleTransmission" >
    <joint name="right_wrist_roll" />
    <actuator name="right_wrist_roll_servo"/>
    <mechanicalReduction>1</mechanicalReduction>
  </transmission>
  <force_element name="tail_force"> 
    <wing chord=".12567" nominal_speed="1" profile="flat plate" span=".23569" stall_angle="181">
      <parent link="tail"/>
  	<origin xyz="0 0 0" rpy="0 0 0"/> 
    </wing>
  </force_element>
  <force_element name="left_mid_wing_force"> 
    <wing chord=".13935" nominal_speed="1" profile="flat plate" span=".09296" stall_angle="181">
      <parent link="left_mid_wing"/>
  	<origin xyz="0 0 0" rpy="0 0 0"/> 
    </wing>
  </force_element>
  <force_element name="left_hand_wing_force"> 
    <wing chord=".11067" nominal_speed="1" profile="flat plate" span=".14572" stall_angle="181">
      <parent link="left_hand_wing"/>
  	<origin xyz="0 0 0" rpy="0 0 0"/> 
    </wing>
  </force_element>
  <force_element name="right_mid_wing_force"> 
    <wing chord=".13935" nominal_speed="1" profile="flat plate" span=".09296" stall_angle="181">
      <parent link="right_mid_wing"/>
  	<origin xyz="0 0 0" rpy="0 0 0"/> 
    </wing>
  </force_element>
  <force_element name="right_hand_wing_force"> 
    <wing chord=".11067" nominal_speed="1" profile="flat plate" span=".14572" stall_angle="181">
      <parent link="right_hand_wing"/>
  	<origin xyz="0 0 0" rpy="0 0 0"/> 
    </wing>
  </force_element>
  <force_element name="tail_spring">
    <torsional_spring stiffness="0.005" rest_angle="0">
      <joint name="tail_joint" />
    </torsional_spring>
  </force_element>
  <force_element name="left_shoulder_roll_spring">
    <torsional_spring stiffness="0.1" rest_angle="0">
      <joint name="left_shoulder_roll" />
    </torsional_spring>
  </force_element>
  <force_element name="left_shoulder_pitch_spring">
    <torsional_spring stiffness="0.1" rest_angle="0">
      <joint name="left_shoulder_pitch" />
    </torsional_spring>
  </force_element>
  <force_element name="left_shoulder_yaw_spring">
    <torsional_spring stiffness="0.1" rest_angle="0">
      <joint name="left_shoulder_yaw" />
    </torsional_spring>
  </force_element>
  <force_element name="left_elbow_roll_spring">
    <torsional_spring stiffness="0.05" rest_angle="0">
      <joint name="left_elbow_roll" />
    </torsional_spring>
  </force_element>
  <force_element name="left_elbow_pitch_spring">
    <torsional_spring stiffness="0.05" rest_angle="0">
      <joint name="left_elbow_pitch" />
    </torsional_spring>
  </force_element>
  <force_element name="left_elbow_yaw_spring">
    <torsional_spring stiffness="0.05" rest_angle="0">
      <joint name="left_elbow_yaw" />
    </torsional_spring>
  </force_element>
  <force_element name="left_wrist_roll_spring">
    <torsional_spring stiffness="0.005" rest_angle="0">
      <joint name="left_wrist_roll" />
    </torsional_spring>
  </force_element>
  <force_element name="right_shoulder_roll_spring">
    <torsional_spring stiffness="0.1" rest_angle="0">
      <joint name="right_shoulder_roll" />
    </torsional_spring>
  </force_element>
  <force_element name="right_shoulder_pitch_spring">
    <torsional_spring stiffness="0.1" rest_angle="0">
      <joint name="right_shoulder_pitch" />
    </torsional_spring>
  </force_element>
  <force_element name="right_shoulder_yaw_spring">
    <torsional_spring stiffness="0.1" rest_angle="0">
      <joint name="right_shoulder_yaw" />
    </torsional_spring>
  </force_element>
  <force_element name="right_elbow_roll_spring">
    <torsional_spring stiffness="0.05" rest_angle="0">
      <joint name="right_elbow_roll" />
    </torsional_spring>
  </force_element>
  <force_element name="right_elbow_pitch_spring">
    <torsional_spring stiffness="0.05" rest_angle="0">
      <joint name="right_elbow_pitch" />
    </torsional_spring>
  </force_element>
  <force_element name="right_elbow_pitch_spring">
    <torsional_spring stiffness="0.05" rest_angle="0">
      <joint name="right_elbow_yaw" />
    </torsional_spring>
  </force_element>
  <force_element name="right_wrist_roll_spring">
    <torsional_spring stiffness="0.005" rest_angle="0">
      <joint name="right_wrist_roll" />
    </torsional_spring>
  </force_element>
</robot>
