<?xml version="1.0"?>

<robot
  name="pigeon_10">
  <link
    name="torso">
    <inertial>
      <origin
        xyz="-0.132434070149677 -2.92945297478124E-07 -0.00712750625005471"
        rpy="0 0 0" />
      <mass
        value="0.266575552840038" />
      <inertia
        ixx="0.00016350796386525"
        ixy="-1.32757604650755E-08"
        ixz="1.49468441773122E-05"
        iyy="0.000802843103287112"
        iyz="-8.62174508639036E-09"
        izz="0.000857177619968798" />
    </inertial>
    <visual>
      <origin
        xyz="0 0 0"
        rpy="0 0 0" />
      <geometry>
        <mesh
          filename="../meshes/torso.STL" />
      </geometry>
      <material
        name="">
        <color
          rgba="0.5 0.5 0.5 1" />
      </material>
    </visual>
  </link>
  <link
    name="tail">
    <inertial>
      <origin
        xyz="-0.0367434745368314 1.14634097922214E-17 3.36408472959864E-18"
        rpy="0 0 0" />
      <mass
        value="0.00283414865838335" />
      <inertia
        ixx="9.13466619052064E-06"
        ixy="3.51036877309245E-22"
        ixz="-1.61534958146993E-23"
        iyy="2.346394244564E-06"
        iyz="1.49306100565822E-23"
        izz="1.14735911790603E-05" />
    </inertial>
    <visual>
      <origin
        xyz="0 0 0"
        rpy="0 0 0" />
      <geometry>
        <mesh
          filename="../meshes/tail.STL" />
      </geometry>
      <material
        name="">
        <color
          rgba="0.5 0.5 0.5 1" />
      </material>
    </visual>
  </link>
  <joint
    name="tail_joint"
    type="continuous">
    <origin
      xyz="-0.25849 0 0"
      rpy="0 0 0" />
    <parent
      link="torso" />
    <child
      link="tail" />
    <axis
      xyz="0 1 0" />
    <dynamics
      damping="0.0007" />
  </joint>
  <link
    name="left_shoulder_roll_ghost">
    <inertial>
       <mass
        value="0" />
    </inertial>
  </link>
  <joint
    name="left_shoulder_roll"
    type="continuous">
    <origin
      xyz="-0.08198 0.042 0"
      rpy="0 0 0" />
    <parent
      link="torso" />
    <child
      link="left_shoulder_roll_ghost" />
    <axis
      xyz="-1 0 0" />
    <dynamics
      damping="0.001" />
  </joint>
  <link
    name="left_shoulder_pitch_ghost">
    <inertial>
       <mass
        value="0" />
    </inertial>
  </link>
  <joint
    name="left_shoulder_pitch"
    type="continuous">
    <origin
      xyz="0 0 0"
      rpy="0 0 0" />
    <parent
      link="left_shoulder_roll_ghost" />
    <child
      link="left_shoulder_pitch_ghost" />
    <axis
      xyz="0 1 0" />
    <dynamics
      damping="0.001" />
  </joint>
  <link
    name="left_upper_wing">
    <inertial>
      <origin
        xyz="-0.0543039239207449 0.0218027728742861 -1.26519787320575E-08"
        rpy="0 0 0" />
      <mass
        value="0.00478467934314604" />
      <inertia
        ixx="6.85803263309496E-07"
        ixy="-4.41899816252943E-07"
        ixz="3.28097162566753E-12"
        iyy="3.47747506697267E-06"
        iyz="1.43326598501674E-12"
        izz="4.15090260308391E-06" />
    </inertial>
    <visual>
      <origin
        xyz="0 0 0"
        rpy="0 0 0" />
      <geometry>
        <mesh
          filename="../meshes/left_upper_wing.STL" />
      </geometry>
      <material
        name="">
        <color
          rgba="0.5 0.5 0.5 1" />
      </material>
    </visual>
  </link>
  <joint
    name="left_shoulder_yaw"
    type="continuous">
    <origin
      xyz="0 0 0"
      rpy="0 0 0" />
    <parent
      link="left_shoulder_pitch_ghost" />
    <child
      link="left_upper_wing" />
    <axis
      xyz="0 0 -1" />
    <dynamics
      damping="0.001" />
  </joint>
  <link
    name="left_elbow_roll_ghost">
    <inertial>
       <mass
        value="0" />
    </inertial>
  </link>
  <joint
    name="left_elbow_roll"
    type="continuous">
    <origin
      xyz="-0.0150543231592249 0.0419980875771034 0"
      rpy="0 0 0" />
    <parent
      link="left_upper_wing" />
    <child
      link="left_elbow_roll_ghost" />
    <axis
      xyz="-1 0 0" />
    <dynamics
      damping="0.001" />
  </joint>
  <link
    name="left_elbow_pitch_ghost">
    <inertial>
       <mass
        value="0" />
    </inertial>
  </link>
  <joint
    name="left_elbow_pitch"
    type="continuous">
    <origin
      xyz="0 0 0"
      rpy="0 0 0" />
    <parent
      link="left_elbow_roll_ghost" />
    <child
      link="left_elbow_pitch_ghost" />
    <axis
      xyz="0 1 0" />
    <dynamics
      damping="0.001" />
  </joint>
  <link
    name="left_mid_wing">
    <inertial>
      <origin
        xyz="-0.0495486671552646 0.0461463515315644 7.03928810441272E-08"
        rpy="0 0 0" />
      <mass
        value="0.00923222139282933" />
      <inertia
        ixx="6.32076926607803E-06"
        ixy="1.65204671390409E-06"
        ixz="-1.10157923158038E-12"
        iyy="1.13159761781573E-05"
        iyz="2.18214269967381E-11"
        izz="1.76124962714532E-05" />
    </inertial>
    <visual>
      <origin
        xyz="0 0 0"
        rpy="0 0 0" />
      <geometry>
        <mesh
          filename="../meshes/left_mid_wing.STL" />
      </geometry>
      <material
        name="">
        <color
          rgba="0.5 0.5 0.5 1" />
      </material>
    </visual>
  </link>
  <joint
    name="left_elbow_yaw"
    type="continuous">
    <origin
      xyz="0 0 0"
      rpy="0 0 0" />
    <parent
      link="left_elbow_pitch_ghost" />
    <child
      link="left_mid_wing" />
    <axis
      xyz="0 0 -1" />
    <dynamics
      damping="0.001" />
  </joint>
  <link
    name="left_hand_wing">
    <inertial>
      <origin
        xyz="-0.0648836782544586 0.0597835058137272 3.75375052734677E-08"
        rpy="0 0 0" />
      <mass
        value="0.00605546079567201" />
      <inertia
        ixx="9.01715501968103E-06"
        ixy="-1.56448026114718E-06"
        ixz="-4.65471378828143E-13"
        iyy="4.30150583723173E-06"
        iyz="7.40776319335357E-12"
        izz="1.33027567122276E-05" />
    </inertial>
    <visual>
      <origin
        xyz="0 0 0"
        rpy="0 0 0" />
      <geometry>
        <mesh
          filename="../meshes/left_hand_wing.STL" />
      </geometry>
      <material
        name="">
        <color
          rgba="0.5 0.5 0.5 1" />
      </material>
    </visual>
  </link>
  <joint
    name="left_wrist_roll"
    type="continuous">
    <origin
      xyz="0.0190702213237429 0.0929625657844593 0"
      rpy="0 0 0" />
    <parent
      link="left_mid_wing" />
    <child
      link="left_hand_wing" />
    <axis
      xyz="-1 0 0" />
    <dynamics
      damping="0.0007" />
  </joint>
  <link
    name="right_shoulder_roll_ghost">
    <inertial>
       <mass
        value="0" />
    </inertial>
  </link>
  <joint
    name="right_shoulder_roll"
    type="continuous">
    <origin
      xyz="-0.081979541052234 -0.042 0"
      rpy="3.14159265358979 0 0" />
    <parent
      link="torso" />
    <child
      link="right_shoulder_roll_ghost" />
    <axis
      xyz="-1 0 0" />
    <dynamics
      damping="0.001" />
  </joint>
  <link
    name="right_shoulder_pitch_ghost">
    <inertial>
       <mass
        value="0" />
    </inertial>
  </link>
  <joint
    name="right_shoulder_pitch"
    type="continuous">
    <origin
      xyz="0 0 0"
      rpy="0 0 0" />
    <parent
      link="right_shoulder_roll_ghost" />
    <child
      link="right_shoulder_pitch_ghost" />
    <axis
      xyz="0 1 0" />
    <dynamics
      damping="0.001" />
  </joint>
  <link
    name="right_upper_wing">
    <inertial>
      <origin
        xyz="-0.0543039239207449 0.0218027728742861 -1.26519787320575E-08"
        rpy="0 0 0" />
      <mass
        value="0.00478467934314604" />
      <inertia
        ixx="6.85803263309496E-07"
        ixy="-4.41899816252943E-07"
        ixz="3.28097162566753E-12"
        iyy="3.47747506697267E-06"
        iyz="1.43326598501674E-12"
        izz="4.15090260308391E-06" />
    </inertial>
    <visual>
      <origin
        xyz="0 0 0"
        rpy="0 0 0" />
      <geometry>
        <mesh
          filename="../meshes/right_upper_wing.STL" />
      </geometry>
      <material
        name="">
        <color
          rgba="0.5 0.5 0.5 1" />
      </material>
    </visual>
  </link>
  <joint
    name="right_shoulder_yaw"
    type="continuous">
    <origin
      xyz="0 0 0"
      rpy="0 0 0" />
    <parent
      link="right_shoulder_pitch_ghost" />
    <child
      link="right_upper_wing" />
    <axis
      xyz="0 0 -1" />
    <dynamics
      damping="0.001" />
  </joint>
  <link
    name="right_elbow_roll_ghost">
    <inertial>
       <mass
        value="0" />
    </inertial>
  </link>
  <joint
    name="right_elbow_roll"
    type="continuous">
    <origin
      xyz="-0.0150543231592249 0.0419980875771034 0"
      rpy="0 0 0" />
    <parent
      link="right_upper_wing" />
    <child
      link="right_elbow_roll_ghost" />
    <axis
      xyz="-1 0 0" />
    <dynamics
      damping="0.001" />
  </joint>
  <link
    name="right_elbow_pitch_ghost">
    <inertial>
       <mass
        value="0" />
    </inertial>
  </link>
  <joint
    name="right_elbow_pitch"
    type="continuous">
    <origin
      xyz="0 0 0"
      rpy="0 0 0" />
    <parent
      link="right_elbow_roll_ghost" />
    <child
      link="right_elbow_pitch_ghost" />
    <axis
      xyz="0 1 0" />
    <dynamics
      damping="0.001" />
  </joint>
  <link
    name="right_mid_wing">
    <inertial>
      <origin
        xyz="-0.0495486671552646 0.0461463515315644 7.03928810441272E-08"
        rpy="0 0 0" />
      <mass
        value="0.00923222139282933" />
      <inertia
        ixx="6.32076926607803E-06"
        ixy="1.65204671390409E-06"
        ixz="-1.10157923158038E-12"
        iyy="1.13159761781573E-05"
        iyz="2.18214269967381E-11"
        izz="1.76124962714532E-05" />
    </inertial>
    <visual>
      <origin
        xyz="0 0 0"
        rpy="0 0 0" />
      <geometry>
        <mesh
          filename="../meshes/right_mid_wing.STL" />
      </geometry>
      <material
        name="">
        <color
          rgba="0.5 0.5 0.5 1" />
      </material>
    </visual>
  </link>
  <joint
    name="right_elbow_yaw"
    type="continuous">
    <origin
      xyz="0 0 0"
      rpy="0 0 0" />
    <parent
      link="right_elbow_pitch_ghost" />
    <child
      link="right_mid_wing" />
    <axis
      xyz="0 0 -1" />
    <dynamics
      damping="0.001" />
  </joint>
  <link
    name="right_hand_wing">
    <inertial>
      <origin
        xyz="-0.0648836782544586 0.0597835058137273 3.75375052734586E-08"
        rpy="0 0 0" />
      <mass
        value="0.00605546079567201" />
      <inertia
        ixx="9.01715501968103E-06"
        ixy="-1.56448026114718E-06"
        ixz="-4.65471378829106E-13"
        iyy="4.30150583723173E-06"
        iyz="7.40776319335155E-12"
        izz="1.33027567122276E-05" />
    </inertial>
    <visual>
      <origin
        xyz="0 0 0"
        rpy="0 0 0" />
      <geometry>
        <mesh
          filename="../meshes/right_hand_wing.STL" />
      </geometry>
      <material
        name="">
        <color
          rgba="0.5 0.5 0.5 1" />
      </material>
    </visual>
  </link>
  <joint
    name="right_wrist_roll"
    type="continuous">
    <origin
      xyz="0.0190702213237429 0.0929625657844593 0"
      rpy="0 0 0" />
    <parent
      link="right_mid_wing" />
    <child
      link="right_hand_wing" />
    <axis
      xyz="-1 0 0" />
    <dynamics
      damping="0.0007" />
  </joint>

  <transmission name="tail_joint_torque" type="SimpleTransmission" >
    <joint name="tail_joint" />
    <actuator name="tail_joint_servo"/>
    <mechanicalReduction>1</mechanicalReduction>
  </transmission>
  <transmission name="left_shoulder_roll_torque" type="SimpleTransmission" >
    <joint name="left_shoulder_roll" />
    <actuator name="left_shoulder_roll_servo"/>
    <mechanicalReduction>1</mechanicalReduction>
  </transmission>
  <transmission name="left_shoulder_pitch_torque" type="SimpleTransmission" >
    <joint name="left_shoulder_pitch" />
    <actuator name="left_shoulder_pitch_servo"/>
    <mechanicalReduction>1</mechanicalReduction>
  </transmission>
  <transmission name="left_shoulder_yaw_torque" type="SimpleTransmission" >
    <joint name="left_shoulder_yaw" />
    <actuator name="left_shoulder_yaw_servo"/>
    <mechanicalReduction>1</mechanicalReduction>
  </transmission>
  <transmission name="left_elbow_roll_torque" type="SimpleTransmission" >
    <joint name="left_elbow_roll" />
    <actuator name="left_elbow_roll_servo"/>
    <mechanicalReduction>1</mechanicalReduction>
  </transmission>
  <transmission name="left_elbow_pitch_torque" type="SimpleTransmission" >
    <joint name="left_elbow_pitch" />
    <actuator name="left_elbow_pitch_servo"/>
    <mechanicalReduction>1</mechanicalReduction>
  </transmission>
  <transmission name="left_elbow_yaw_torque" type="SimpleTransmission" >
    <joint name="left_elbow_yaw" />
    <actuator name="left_elbow_yaw_servo"/>
    <mechanicalReduction>1</mechanicalReduction>
  </transmission>
  <transmission name="left_wrist_roll_torque" type="SimpleTransmission" >
    <joint name="left_wrist_roll" />
    <actuator name="left_wrist_roll_servo"/>
    <mechanicalReduction>1</mechanicalReduction>
  </transmission>
  <transmission name="right_shoulder_roll_torque" type="SimpleTransmission" >
    <joint name="right_shoulder_roll" />
    <actuator name="right_shoulder_roll_servo"/>
    <mechanicalReduction>1</mechanicalReduction>
  </transmission>
  <transmission name="right_shoulder_pitch_torque" type="SimpleTransmission" >
    <joint name="right_shoulder_pitch" />
    <actuator name="right_shoulder_pitch_servo"/>
    <mechanicalReduction>1</mechanicalReduction>
  </transmission>
  <transmission name="right_shoulder_yaw_torque" type="SimpleTransmission" >
    <joint name="right_shoulder_yaw" />
    <actuator name="right_shoulder_yaw_servo"/>
    <mechanicalReduction>1</mechanicalReduction>
  </transmission>
  <transmission name="right_elbow_roll_torque" type="SimpleTransmission" >
    <joint name="right_elbow_roll" />
    <actuator name="right_elbow_roll_servo"/>
    <mechanicalReduction>1</mechanicalReduction>
  </transmission>
  <transmission name="right_elbow_pitch_torque" type="SimpleTransmission" >
    <joint name="right_elbow_pitch" />
    <actuator name="right_elbow_pitch_servo"/>
    <mechanicalReduction>1</mechanicalReduction>
  </transmission>
  <transmission name="right_elbow_yaw_torque" type="SimpleTransmission" >
    <joint name="right_elbow_yaw" />
    <actuator name="right_elbow_yaw_servo"/>
    <mechanicalReduction>1</mechanicalReduction>
  </transmission>
  <transmission name="right_wrist_roll_torque" type="SimpleTransmission" >
    <joint name="right_wrist_roll" />
    <actuator name="right_wrist_roll_servo"/>
    <mechanicalReduction>1</mechanicalReduction>
  </transmission>

  <force_element name="tail_force"> 
    <wing chord=".12567" nominal_speed="1" profile="flat plate" span=".23569" stall_angle="181">
      <parent link="tail"/>
  	<origin xyz="0 0 0" rpy="0 0 0"/> 
    </wing>
  </force_element>
  <force_element name="left_mid_wing_force"> 
    <wing chord=".13935" nominal_speed="1" profile="flat plate" span=".09296" stall_angle="181">
      <parent link="left_mid_wing"/>
  	<origin xyz="0 0 0" rpy="0 0 0"/> 
    </wing>
  </force_element>
  <force_element name="left_hand_wing_force"> 
    <wing chord=".11067" nominal_speed="1" profile="flat plate" span=".14572" stall_angle="181">
      <parent link="left_hand_wing"/>
  	<origin xyz="0 0 0" rpy="0 0 0"/> 
    </wing>
  </force_element>
  <force_element name="right_mid_wing_force"> 
    <wing chord=".13935" nominal_speed="1" profile="flat plate" span=".09296" stall_angle="181">
      <parent link="right_mid_wing"/>
  	<origin xyz="0 0 0" rpy="0 0 0"/> 
    </wing>
  </force_element>
  <force_element name="right_hand_wing_force"> 
    <wing chord=".11067" nominal_speed="1" profile="flat plate" span=".14572" stall_angle="181">
      <parent link="right_hand_wing"/>
  	<origin xyz="0 0 0" rpy="0 0 0"/> 
    </wing> 
  </force_element>
  <force_element name="tail_spring">
    <torsional_spring stiffness="0.005" rest_angle="0">
      <joint name="tail_joint" />
    </torsional_spring>
  </force_element>
  <force_element name="left_shoulder_roll_spring">
    <torsional_spring stiffness="0.1" rest_angle="0">
      <joint name="left_shoulder_roll" />
    </torsional_spring>
  </force_element>
  <force_element name="left_shoulder_pitch_spring">
    <torsional_spring stiffness="0.1" rest_angle="0">
      <joint name="left_shoulder_pitch" />
    </torsional_spring>
  </force_element>
  <force_element name="left_shoulder_yaw_spring">
    <torsional_spring stiffness="0.1" rest_angle="0">
      <joint name="left_shoulder_yaw" />
    </torsional_spring>
  </force_element>
  <force_element name="left_elbow_roll_spring">
    <torsional_spring stiffness="0.05" rest_angle="0">
      <joint name="left_elbow_roll" />
    </torsional_spring>
  </force_element>
  <force_element name="left_elbow_pitch_spring">
    <torsional_spring stiffness="0.05" rest_angle="0">
      <joint name="left_elbow_pitch" />
    </torsional_spring>
  </force_element>
  <force_element name="left_elbow_yaw_spring">
    <torsional_spring stiffness="0.05" rest_angle="0">
      <joint name="left_elbow_yaw" />
    </torsional_spring>
  </force_element>
  <force_element name="left_wrist_roll_spring">
    <torsional_spring stiffness="0.005" rest_angle="0">
      <joint name="left_wrist_roll" />
    </torsional_spring>
  </force_element>
  <force_element name="right_shoulder_roll_spring">
    <torsional_spring stiffness="0.1" rest_angle="0">
      <joint name="right_shoulder_roll" />
    </torsional_spring>
  </force_element>
  <force_element name="right_shoulder_pitch_spring">
    <torsional_spring stiffness="0.1" rest_angle="0">
      <joint name="right_shoulder_pitch" />
    </torsional_spring>
  </force_element>
  <force_element name="right_shoulder_yaw_spring">
    <torsional_spring stiffness="0.1" rest_angle="0">
      <joint name="right_shoulder_yaw" />
    </torsional_spring>
  </force_element>
  <force_element name="right_elbow_roll_spring">
    <torsional_spring stiffness="0.05" rest_angle="0">
      <joint name="right_elbow_roll" />
    </torsional_spring>
  </force_element>
  <force_element name="right_elbow_pitch_spring">
    <torsional_spring stiffness="0.05" rest_angle="0">
      <joint name="right_elbow_pitch" />
    </torsional_spring>
  </force_element>
  <force_element name="right_elbow_yaw_spring">
    <torsional_spring stiffness="0.05" rest_angle="0">
      <joint name="right_elbow_yaw" />
    </torsional_spring>
  </force_element>
  <force_element name="right_wrist_roll_spring">
    <torsional_spring stiffness="0.005" rest_angle="0">
      <joint name="right_wrist_roll" />
    </torsional_spring>
  </force_element>

</robot>
