<?xml version="1.0"?>

<robot
  name="pigeon_9">
  <link
    name="torso">
    <inertial>
      <origin
        xyz="-0.132434070149677 -0.00712750625005471 2.92945297478124E-07"
        rpy="0 0 0" />
      <mass
        value="0.266575552840038" />
      <inertia
        ixx="0.00016350796386525"
        ixy="1.49468441773122E-05"
        ixz="1.32757604650755E-08"
        iyy="0.000857177619968798"
        iyz="8.62174508639036E-09"
        izz="0.000802843103287112" />
    </inertial>
    <visual>
      <origin
        xyz="0 0 0"
        rpy="0 0 0" />
      <geometry>
        <mesh
          filename="../meshes/torso.STL" />
      </geometry>
      <material
        name="">
        <color
          rgba="0.5 0.5 0.5 1" />
      </material>
    </visual>
  </link>
  <link
    name="tail">
    <inertial>
      <origin
        xyz="-0.0367434745368314 3.35881661848089E-18 -1.18005689037573E-17"
        rpy="0 0 0" />
      <mass
        value="0.00283414865838335" />
      <inertia
        ixx="9.13466619052064E-06"
        ixy="-1.78826691948639E-23"
        ixz="-3.75852965814435E-22"
        iyy="1.14735911790603E-05"
        iyz="-1.35308653637776E-23"
        izz="2.346394244564E-06" />
    </inertial>
    <visual>
      <origin
        xyz="0 0 0"
        rpy="0 0 0" />
      <geometry>
        <mesh
          filename="../meshes/tail.STL" />
      </geometry>
      <material
        name="">
        <color
          rgba="0.5 0.5 0.5 1" />
      </material>
    </visual>
  </link>
  <joint
    name="tail_joint"
    type="continuous">
    <origin
      xyz="-0.25849 0 0"
      rpy="0 0 0" />
    <parent
      link="torso" />
    <child
      link="tail" />
    <axis
      xyz="0 0 -1" />
  </joint>
  <link
    name="left_shoulder_roll_ghost">
    <inertial>
       <mass
        value="0" />
    </inertial>
  </link>
  <joint
    name="left_shoulder_roll"
    type="continuous">
    <origin
      xyz="-0.08198 0 -0.042"
      rpy="0 0 0" />
    <parent
      link="torso" />
    <child
      link="left_shoulder_roll_ghost" />
    <axis
      xyz="-1 0 0" />
  </joint>
  <link
    name="left_shoulder_pitch_ghost">
    <inertial>
       <mass
        value="0" />
    </inertial>
  </link>
  <joint
    name="left_shoulder_pitch"
    type="continuous">
    <origin
      xyz="0 0 0"
      rpy="0 0 0" />
    <parent
      link="left_shoulder_roll_ghost" />
    <child
      link="left_shoulder_pitch_ghost" />
    <axis
      xyz="0 0 1" />
  </joint>
  <link
    name="left_upper_wing">
    <inertial>
      <origin
        xyz="-0.0543039239207449 -1.26519787321426E-08 -0.0218027728742861"
        rpy="0 0 0" />
      <mass
        value="0.00478467934314604" />
      <inertia
        ixx="6.85803263309496E-07"
        ixy="3.28097162568015E-12"
        ixz="4.41899816252943E-07"
        iyy="4.15090260308391E-06"
        iyz="-1.43326598501177E-12"
        izz="3.47747506697267E-06" />
    </inertial>
    <visual>
      <origin
        xyz="0 0 0"
        rpy="0 0 0" />
      <geometry>
        <mesh
          filename="../meshes/left_upper_wing.STL" />
      </geometry>
      <material
        name="">
        <color
          rgba="0.5 0.5 0.5 1" />
      </material>
    </visual>
  </link>
  <joint
    name="left_shoulder_yaw"
    type="continuous">
    <origin
      xyz="0 0 0"
      rpy="0 0 0" />
    <parent
      link="left_shoulder_pitch_ghost" />
    <child
      link="left_upper_wing" />
    <axis
      xyz="0 -1 0" />
  </joint>
  <link
    name="left_elbow_roll_ghost">
    <inertial>
       <mass
        value="0" />
    </inertial>
  </link>
  <joint
    name="left_elbow_roll"
    type="continuous">
    <origin
      xyz="-0.015054 0 -0.041998"
      rpy="0 0 0" />
    <parent
      link="left_upper_wing" />
    <child
      link="left_elbow_roll_ghost" />
    <axis
      xyz="-1 0 0" />
  </joint>
  <link
    name="left_elbow_pitch_ghost">
    <inertial>
       <mass
        value="0" />
    </inertial>
  </link>
  <joint
    name="left_elbow_pitch"
    type="continuous">
    <origin
      xyz="0 0 0"
      rpy="0 0 0" />
    <parent
      link="left_elbow_roll_ghost" />
    <child
      link="left_elbow_pitch_ghost" />
    <axis
      xyz="0 0 1" />
  </joint>
  <link
    name="left_mid_wing">
    <inertial>
      <origin
        xyz="-0.0495486671552646 7.03928810441842E-08 -0.0461463515315644"
        rpy="0 0 0" />
      <mass
        value="0.00923222139282933" />
      <inertia
        ixx="6.32076926607803E-06"
        ixy="-1.1015792315813E-12"
        ixz="-1.65204671390409E-06"
        iyy="1.76124962714532E-05"
        iyz="-2.1821426996728E-11"
        izz="1.13159761781573E-05" />
    </inertial>
    <visual>
      <origin
        xyz="0 0 0"
        rpy="0 0 0" />
      <geometry>
        <mesh
          filename="../meshes/left_mid_wing.STL" />
      </geometry>
      <material
        name="">
        <color
          rgba="0.5 0.5 0.5 1" />
      </material>
    </visual>
  </link>
  <joint
    name="left_elbow_yaw"
    type="continuous">
    <origin
      xyz="0 0 0"
      rpy="0 0 0" />
    <parent
      link="left_elbow_pitch_ghost" />
    <child
      link="left_mid_wing" />
    <axis
      xyz="0 -1 0" />
  </joint>
  <link
    name="left_hand_wing">
    <inertial>
      <origin
        xyz="-0.0648836782544586 3.75375052747031E-08 -0.0597835058137272"
        rpy="0 0 0" />
      <mass
        value="0.00605546079567201" />
      <inertia
        ixx="9.01715501968102E-06"
        ixy="-4.65471378745311E-13"
        ixz="1.56448026114718E-06"
        iyy="1.33027567122276E-05"
        iyz="-7.40776319301286E-12"
        izz="4.30150583723173E-06" />
    </inertial>
    <visual>
      <origin
        xyz="0 0 0"
        rpy="0 0 0" />
      <geometry>
        <mesh
          filename="../meshes/left_hand_wing.STL" />
      </geometry>
      <material
        name="">
        <color
          rgba="0.5 0.5 0.5 1" />
      </material>
    </visual>
  </link>
  <joint
    name="left_wrist_roll"
    type="continuous">
    <origin
      xyz="0.0190702213237429 0 -0.0929625657844593"
      rpy="0 0 0" />
    <parent
      link="left_mid_wing" />
    <child
      link="left_hand_wing" />
    <axis
      xyz="-1 0 0" />
  </joint>
  <link
    name="right_shoulder_roll_ghost">
    <inertial>
       <mass
        value="0" />
    </inertial>
  </link>
  <joint
    name="right_shoulder_roll"
    type="continuous">
    <origin
      xyz="-0.081979541052234 0 0.042"
      rpy="3.14159265358979 0 0" />
    <parent
      link="torso" />
    <child
      link="right_shoulder_roll_ghost" />
    <axis
      xyz="-1 0 0" />
  </joint>
  <link
    name="right_shoulder_pitch_ghost">
    <inertial>
       <mass
        value="0" />
    </inertial>
  </link>
  <joint
    name="right_shoulder_pitch"
    type="continuous">
    <origin
      xyz="0 0 0"
      rpy="0 0 0" />
    <parent
      link="right_shoulder_roll_ghost" />
    <child
      link="right_shoulder_pitch_ghost" />
    <axis
      xyz="0 0 1" />
  </joint>
  <link
    name="right_upper_wing">
    <inertial>
      <origin
        xyz="-0.0543039239207449 -1.26519787321426E-08 -0.0218027728742861"
        rpy="0 0 0" />
      <mass
        value="0.00478467934314604" />
      <inertia
        ixx="6.85803263309496E-07"
        ixy="3.28097162568015E-12"
        ixz="4.41899816252943E-07"
        iyy="4.15090260308391E-06"
        iyz="-1.43326598501177E-12"
        izz="3.47747506697267E-06" />
    </inertial>
    <visual>
      <origin
        xyz="0 0 0"
        rpy="0 0 0" />
      <geometry>
        <mesh
          filename="../meshes/right_upper_wing.STL" />
      </geometry>
      <material
        name="">
        <color
          rgba="0.5 0.5 0.5 1" />
      </material>
    </visual>
  </link>
  <joint
    name="right_shoulder_yaw"
    type="continuous">
    <origin
      xyz="0 0 0"
      rpy="0 0 0" />
    <parent
      link="right_shoulder_pitch_ghost" />
    <child
      link="right_upper_wing" />
    <axis
      xyz="0 -1 0" />
  </joint>
  <link
    name="right_elbow_roll_ghost">
    <inertial>
       <mass
        value="0" />
    </inertial>
  </link>
  <joint
    name="right_elbow_roll"
    type="continuous">
    <origin
      xyz="-0.0150543231592249 0 -0.0419980875771034"
      rpy="0 0 0" />
    <parent
      link="right_upper_wing" />
    <child
      link="right_elbow_roll_ghost" />
    <axis
      xyz="-1 0 0" />
  </joint>
  <link
    name="right_elbow_pitch_ghost">
    <inertial>
       <mass
        value="0" />
    </inertial>
  </link>
  <joint
    name="right_elbow_pitch"
    type="continuous">
    <origin
      xyz="0 0 0"
      rpy="0 0 0" />
    <parent
      link="right_elbow_roll_ghost" />
    <child
      link="right_elbow_pitch_ghost" />
    <axis
      xyz="0 0 1" />
  </joint>
  <link
    name="right_mid_wing">
    <inertial>
      <origin
        xyz="-0.0495486671552646 7.03928810441842E-08 -0.0461463515315644"
        rpy="0 0 0" />
      <mass
        value="0.00923222139282933" />
      <inertia
        ixx="6.32076926607803E-06"
        ixy="-1.1015792315813E-12"
        ixz="-1.65204671390409E-06"
        iyy="1.76124962714532E-05"
        iyz="-2.1821426996728E-11"
        izz="1.13159761781573E-05" />
    </inertial>
    <visual>
      <origin
        xyz="0 0 0"
        rpy="0 0 0" />
      <geometry>
        <mesh
          filename="../meshes/right_mid_wing.STL" />
      </geometry>
      <material
        name="">
        <color
          rgba="0.5 0.5 0.5 1" />
      </material>
    </visual>
  </link>
  <joint
    name="right_elbow_yaw"
    type="continuous">
    <origin
      xyz="0 0 0"
      rpy="0 0 0" />
    <parent
      link="right_elbow_pitch_ghost" />
    <child
      link="right_mid_wing" />
    <axis
      xyz="0 -1 0" />
  </joint>
  <link
    name="right_hand_wing">
    <inertial>
      <origin
        xyz="-0.0648836782544586 3.75375052747031E-08 -0.0597835058137272"
        rpy="0 0 0" />
      <mass
        value="0.00605546079567201" />
      <inertia
        ixx="9.01715501968102E-06"
        ixy="-4.65471378745311E-13"
        ixz="1.56448026114718E-06"
        iyy="1.33027567122276E-05"
        iyz="-7.40776319301286E-12"
        izz="4.30150583723173E-06" />
    </inertial>
    <visual>
      <origin
        xyz="0 0 0"
        rpy="0 0 0" />
      <geometry>
        <mesh
          filename="../meshes/right_hand_wing.STL" />
      </geometry>
      <material
        name="">
        <color
          rgba="0.5 0.5 0.5 1" />
      </material>
    </visual>
  </link>
  <joint
    name="right_wrist_roll"
    type="continuous">
    <origin
      xyz="0.0190702213237429 0 -0.0929625657844593"
      rpy="0 0 0" />
    <parent
      link="right_mid_wing" />
    <child
      link="right_hand_wing" />
    <axis
      xyz="-1 0 0" />
  </joint>
</robot>
