<?xml version="1.0"?>

<robot
  name="pigeon_4">
  <link
    name="base_link">
    <inertial>
      <origin
        xyz="0.132434070149677 -0.00712750625005472 -2.92945297809296E-07"
        rpy="0 0 0" />
      <mass
        value="0.266575552840038" />
      <inertia
        ixx="0.00016350796386525"
        ixy="-1.49468441773122E-05"
        ixz="1.3275760462711E-08"
        iyy="0.000857177619968799"
        iyz="-8.62174508630343E-09"
        izz="0.000802843103287113" />
    </inertial>
    <visual>
      <origin
        xyz="0 0 0"
        rpy="0 0 0" />
      <geometry>
        <mesh
          filename="../meshes/base_link.STL" />
      </geometry>
      <material
        name="">
        <color
          rgba="0.792156862745098 0.819607843137255 0.933333333333333 1" />
      </material>
    </visual>
  </link>
  <link
    name="tail">
    <inertial>
      <origin
        xyz="1.03696254265466E-15 3.25477142390535E-18 0.0652517307094302"
        rpy="0 0 0" />
      <mass
        value="0.00283414865838335" />
      <inertia
        ixx="2.346394244564E-06"
        ixy="-4.57249932982828E-23"
        ixz="-2.43392028342859E-20"
        iyy="1.14735911790603E-05"
        iyz="-9.70072976911944E-24"
        izz="9.13466619052064E-06" />
    </inertial>
    <visual>
      <origin
        xyz="0 0 0"
        rpy="0 0 0" />
      <geometry>
        <mesh
          filename="../meshes/tail.STL" />
      </geometry>
      <material
        name="">
        <color
          rgba="0.792156862745098 0.819607843137255 0.933333333333333 1" />
      </material>
    </visual>
  </link>
  <joint
    name="tail_joint"
    type="continuous">
    <origin
      xyz="0.229979541052234 0 0"
      rpy="1.5707963267949 6.12303176911189E-17 1.5707963267949" />
    <parent
      link="base_link" />
    <child
      link="tail" />
    <axis
      xyz="1 0 0" />
  </joint>
  <link
    name="left_shoulder_roll_ghost">
    <inertial>
      <mass
        value="0" />
    </inertial>
  </link>
  <joint
    name="left_shoulder_roll"
    type="continuous">
    <origin
      xyz="0.0769795410522341 -0.0419999999999997 0"
      rpy="1.5707963267949 6.12303176911189E-17 1.5707963267949" />
    <parent
      link="base_link" />
    <child
      link="left_shoulder_roll_ghost" />
    <axis
      xyz="0 0 -1" />
  </joint>
  <link
    name="left_shoulder_pitch_ghost">
    <inertial>
      <mass
        value="0" />
    </inertial>
  </link>
  <joint
    name="left_shoulder_pitch"
    type="continuous">
    <origin
      xyz="0 0 0"
      rpy="0 0 0" />
    <parent
      link="left_shoulder_roll_ghost" />
    <child
      link="left_shoulder_pitch_ghost" />
    <axis
      xyz="1 0 0" />
  </joint>
  <link
    name="left_upper_wing">
    <inertial>
      <origin
        xyz="-0.0218027728742861 -1.2651978750821E-08 0.059303923920745"
        rpy="0 0 0" />
      <mass
        value="0.00478467934314601" />
      <inertia
        ixx="3.47747506697266E-06"
        ixy="-1.43326598484803E-12"
        ixz="-4.41899816252931E-07"
        iyy="4.15090260308389E-06"
        iyz="-3.28097162562305E-12"
        izz="6.85803263309488E-07" />
    </inertial>
    <visual>
      <origin
        xyz="0 0 0"
        rpy="0 0 0" />
      <geometry>
        <mesh
          filename="../meshes/left_upper_wing.STL" />
      </geometry>
      <material
        name="">
        <color
          rgba="0.792156862745098 0.819607843137255 0.933333333333333 1" />
      </material>
    </visual>
  </link>
  <joint
    name="left_shoulder_yaw"
    type="continuous">
    <origin
      xyz="0 0 0"
      rpy="0 0 0" />
    <parent
      link="left_shoulder_pitch_ghost" />
    <child
      link="left_upper_wing" />
    <axis
      xyz="0 -1 0" />
  </joint>
  <link
    name="left_elbow_roll_ghost">
    <inertial>
      <mass
        value="0" />
    </inertial>
  </link>
  <joint
    name="left_elbow_roll"
    type="continuous">
    <origin
      xyz="-0.0419980875771035 0 0.0150543231592251"
      rpy="0 0 0" />
    <parent
      link="left_upper_wing" />
    <child
      link="left_elbow_roll_ghost" />
    <axis
      xyz="0 0 -1" />
  </joint>
  <link
    name="left_elbow_pitch_ghost">
    <inertial>
      <mass
        value="0" />
    </inertial>
  </link>
  <joint
    name="left_elbow_pitch"
    type="continuous">
    <origin
      xyz="0 0 0"
      rpy="0 0 0" />
    <parent
      link="left_elbow_roll_ghost" />
    <child
      link="left_elbow_pitch_ghost" />
    <axis
      xyz="1 0 0" />
  </joint>
  <link
    name="left_mid_wing">
    <inertial>
      <origin
        xyz="-0.046146351531564 7.03928810340763E-08 0.0545486671552649"
        rpy="0 0 0" />
      <mass
        value="0.00923222139282933" />
      <inertia
        ixx="1.13159761781582E-05"
        ixy="-2.18214269953283E-11"
        ixz="1.65204671390397E-06"
        iyy="1.76124962714541E-05"
        iyz="1.10157923234371E-12"
        izz="6.32076926607802E-06" />
    </inertial>
    <visual>
      <origin
        xyz="0 0 0"
        rpy="0 0 0" />
      <geometry>
        <mesh
          filename="../meshes/left_mid_wing.STL" />
      </geometry>
      <material
        name="">
        <color
          rgba="0.792156862745098 0.819607843137255 0.933333333333333 1" />
      </material>
    </visual>
  </link>
  <joint
    name="left_elbow_yaw"
    type="continuous">
    <origin
      xyz="0 0 0"
      rpy="0 0 0" />
    <parent
      link="left_elbow_pitch_ghost" />
    <child
      link="left_mid_wing" />
    <axis
      xyz="0 -1 0" />
  </joint>
  <link
    name="left_hand_wing">
    <inertial>
      <origin
        xyz="0.0859393285876489 0.00200003753750527 -0.0744650030260771"
        rpy="0 0 0" />
      <mass
        value="0.00605546079567198" />
      <inertia
        ixx="4.30150583723843E-06"
        ixy="-7.40776319336573E-12"
        ixz="-1.56448026114783E-06"
        iyy="1.33027567122342E-05"
        iyz="4.65471379000121E-13"
        izz="9.01715501968094E-06" />
    </inertial>
    <visual>
      <origin
        xyz="0 0 0"
        rpy="0 0 0" />
      <geometry>
        <mesh
          filename="../meshes/left_hand_wing.STL" />
      </geometry>
      <material
        name="">
        <color
          rgba="0.792156862745098 0.819607843137255 0.933333333333333 1" />
      </material>
    </visual>
  </link>
  <joint
    name="left_wrist_roll"
    type="continuous">
    <origin
      xyz="-0.238685400185835 -0.00200000000000001 0.125278459956794"
      rpy="0 0 0" />
    <parent
      link="left_mid_wing" />
    <child
      link="left_hand_wing" />
    <axis
      xyz="0 0 1" />
  </joint>
  <link
    name="right_shoulder_roll_ghost">
    <inertial>
      <mass
        value="0" />
    </inertial>
  </link>
  <joint
    name="right_shoulder_roll"
    type="continuous">
    <origin
      xyz="0.0869795410522339 0.0370000000000003 -0.00500000000000001"
      rpy="1.5707963267949 6.12303176911189E-17 1.5707963267949" />
    <parent
      link="base_link" />
    <child
      link="right_shoulder_roll_ghost" />
    <axis
      xyz="0 0 1" />
  </joint>
  <link
    name="right_shoulder_pitch_ghost">
    <inertial>
      <mass
        value="0" />
    </inertial>
  </link>
  <joint
    name="right_shoulder_pitch"
    type="continuous">
    <origin
      xyz="0 0 0"
      rpy="0 0 0" />
    <parent
      link="right_shoulder_roll_ghost" />
    <child
      link="right_shoulder_pitch_ghost" />
    <axis
      xyz="1 0 0" />
  </joint>
  <link
    name="right_upper_wing">
    <inertial>
      <origin
        xyz="0.258880714888653 -0.00199998734802126 0.0810288591952717"
        rpy="0 0 0" />
      <mass
        value="0.00478467934314604" />
      <inertia
        ixx="3.47747506697266E-06"
        ixy="1.43326598456437E-12"
        ixz="4.41899816252951E-07"
        iyy="4.1509026030839E-06"
        iyz="-3.28097162588813E-12"
        izz="6.85803263309498E-07" />
    </inertial>
    <visual>
      <origin
        xyz="0 0 0"
        rpy="0 0 0" />
      <geometry>
        <mesh
          filename="../meshes/right_upper_wing.STL" />
      </geometry>
      <material
        name="">
        <color
          rgba="0.792156862745098 0.819607843137255 0.933333333333333 1" />
      </material>
    </visual>
  </link>
  <joint
    name="right_shoulder_yaw"
    type="continuous">
    <origin
      xyz="0.28568348776294 0.00700000000000001 0.130332783116016"
      rpy="3.14159265358979 0 3.14159265358979" />
    <parent
      link="right_shoulder_pitch_ghost" />
    <child
      link="right_upper_wing" />
    <axis
      xyz="0 -1 0" />
  </joint>
  <link
    name="right_elbow_roll_ghost">
    <inertial>
      <mass
        value="0" />
    </inertial>
  </link>
  <joint
    name="right_elbow_roll"
    type="continuous">
    <origin
      xyz="0.238685400185836 -0.002 0.115278459956792"
      rpy="3.14159265358979 0 3.14159265358979" />
    <parent
      link="right_upper_wing" />
    <child
      link="right_elbow_roll_ghost" />
    <axis
      xyz="0 0 -1" />
  </joint>
  <link
    name="right_elbow_pitch_ghost">
    <inertial>
      <mass
        value="0" />
    </inertial>
  </link>
  <joint
    name="right_elbow_pitch"
    type="continuous">
    <origin
      xyz="0 0 0"
      rpy="0 0 0" />
    <parent
      link="right_elbow_roll_ghost" />
    <child
      link="right_elbow_pitch_ghost" />
    <axis
      xyz="1 0 0" />
  </joint>
  <link
    name="right_mid_wing">
    <inertial>
      <origin
        xyz="-0.0461463515315648 -7.03928810438927E-08 -0.0445486671552643"
        rpy="0 0 0" />
      <mass
        value="0.00923222139282937" />
      <inertia
        ixx="1.13159761781575E-05"
        ixy="2.18214269969603E-11"
        ixz="-1.65204671390386E-06"
        iyy="1.76124962714535E-05"
        iyz="1.1015792315388E-12"
        izz="6.32076926607808E-06" />
    </inertial>
    <visual>
      <origin
        xyz="0 0 0"
        rpy="0 0 0" />
      <geometry>
        <mesh
          filename="../meshes/right_mid_wing.STL" />
      </geometry>
      <material
        name="">
        <color
          rgba="0.792156862745098 0.819607843137255 0.933333333333333 1" />
      </material>
    </visual>
  </link>
  <joint
    name="right_elbow_yaw"
    type="continuous">
    <origin
      xyz="0 0 0"
      rpy="3.14159265358979 1.38777878078145E-15 3.14159265358979" />
    <parent
      link="right_elbow_pitch_ghost" />
    <child
      link="right_mid_wing" />
    <axis
      xyz="0 -1 0" />
  </joint>
  <link
    name="right_hand_wing">
    <inertial>
      <origin
        xyz="-0.0597835058137272 -3.75375052626035E-08 -0.0408134569307155"
        rpy="0 0 0" />
      <mass
        value="0.00605546079567203" />
      <inertia
        ixx="4.30150583723637E-06"
        ixy="7.40776319550178E-12"
        ixz="1.56448026114821E-06"
        iyy="1.33027567122327E-05"
        iyz="4.65471378908723E-13"
        izz="9.01715501968141E-06" />
    </inertial>
    <visual>
      <origin
        xyz="0 0 0"
        rpy="0 0 0" />
      <geometry>
        <mesh
          filename="../meshes/right_hand_wing.STL" />
      </geometry>
      <material
        name="">
        <color
          rgba="0.792156862745098 0.819607843137255 0.933333333333333 1" />
      </material>
    </visual>
  </link>
  <joint
    name="right_wrist_roll"
    type="continuous">
    <origin
      xyz="-0.0929625657844593 0 0"
      rpy="0 1.38777878078145E-15 0" />
    <parent
      link="right_mid_wing" />
    <child
      link="right_hand_wing" />
    <axis
      xyz="0 0 1" />
  </joint>

  <transmission name="tail_joint_torque" type="SimpleTransmission" >
    <joint name="tail_joint" />
    <actuator name="tail_joint_servo"/>
    <mechanicalReduction>1</mechanicalReduction>
  </transmission>

  <transmission name="left_shoulder_roll_torque" type="SimpleTransmission" >
    <joint name="left_shoulder_roll" />
    <actuator name="left_shoulder_roll_servo"/>
    <mechanicalReduction>1</mechanicalReduction>
  </transmission>

  <transmission name="left_shoulder_pitch_torque" type="SimpleTransmission" >
    <joint name="left_shoulder_pitch" />
    <actuator name="left_shoulder_pitch_servo"/>
    <mechanicalReduction>1</mechanicalReduction>
  </transmission>

  <transmission name="left_shoulder_yaw_torque" type="SimpleTransmission" >
    <joint name="left_shoulder_yaw" />
    <actuator name="left_shoulder_yaw_servo"/>
    <mechanicalReduction>1</mechanicalReduction>
  </transmission>

  <transmission name="left_elbow_roll_torque" type="SimpleTransmission" >
    <joint name="left_elbow_roll" />
    <actuator name="left_elbow_roll_servo"/>
    <mechanicalReduction>1</mechanicalReduction>
  </transmission>

  <transmission name="left_elbow_pitch_torque" type="SimpleTransmission" >
    <joint name="left_elbow_pitch" />
    <actuator name="left_elbow_pitch_servo"/>
    <mechanicalReduction>1</mechanicalReduction>
  </transmission>

  <transmission name="left_elbow_yaw_torque" type="SimpleTransmission" >
    <joint name="left_elbow_yaw" />
    <actuator name="left_elbow_yaw_servo"/>
    <mechanicalReduction>1</mechanicalReduction>
  </transmission>

  <transmission name="left_wrist_roll_torque" type="SimpleTransmission" >
    <joint name="left_wrist_roll" />
    <actuator name="left_wrist_roll_servo"/>
    <mechanicalReduction>1</mechanicalReduction>
  </transmission>

  <transmission name="right_shoulder_roll_torque" type="SimpleTransmission" >
    <joint name="right_shoulder_roll" />
    <actuator name="right_shoulder_roll_servo"/>
    <mechanicalReduction>1</mechanicalReduction>
  </transmission>

  <transmission name="right_shoulder_pitch_torque" type="SimpleTransmission" >
    <joint name="right_shoulder_pitch" />
    <actuator name="right_shoulder_pitch_servo"/>
    <mechanicalReduction>1</mechanicalReduction>
  </transmission>

  <transmission name="right_shoulder_yaw_torque" type="SimpleTransmission" >
    <joint name="right_shoulder_yaw" />
    <actuator name="right_shoulder_yaw_servo"/>
    <mechanicalReduction>1</mechanicalReduction>
  </transmission>

  <transmission name="right_elbow_roll_torque" type="SimpleTransmission" >
    <joint name="right_elbow_roll" />
    <actuator name="right_elbow_roll_servo"/>
    <mechanicalReduction>1</mechanicalReduction>
  </transmission>

  <transmission name="right_elbow_pitch_torque" type="SimpleTransmission" >
    <joint name="right_elbow_pitch" />
    <actuator name="right_elbow_pitch_servo"/>
    <mechanicalReduction>1</mechanicalReduction>
  </transmission>

  <transmission name="right_elbow_yaw_torque" type="SimpleTransmission" >
    <joint name="right_elbow_yaw" />
    <actuator name="right_elbow_yaw_servo"/>
    <mechanicalReduction>1</mechanicalReduction>
  </transmission>

  <transmission name="right_wrist_roll_torque" type="SimpleTransmission" >
    <joint name="right_wrist_roll" />
    <actuator name="right_wrist_roll_servo"/>
    <mechanicalReduction>1</mechanicalReduction>
  </transmission>



  <force_element name="tail_force"> 
    <wing chord=".12567" nominal_speed="1" profile="flat plate" span=".23569" stall_angle="181">
      <parent link="tail"/>
  	<origin xyz="0 0 0" rpy="0 0 0"/> 
    </wing>
  </force_element>
<!--
  <force_element name="left_upper_wing_force"> 
    <wing chord=".08481" nominal_speed="1" profile="flat plate" span=".042" stall_angle="181">
      <parent link="left_upper_wing"/>
  	<origin xyz="0 0 0" rpy="0 0 0"/> 
    </wing>
  </force_element>
-->
  <force_element name="left_mid_wing_force"> 
    <wing chord=".13935" nominal_speed="1" profile="flat plate" span=".09296" stall_angle="181">
      <parent link="left_mid_wing"/>
  	<origin xyz="0 0 0" rpy="0 0 0"/> 
    </wing>
  </force_element>
  <force_element name="left_hand_wing_force"> 
    <wing chord=".11067" nominal_speed="1" profile="flat plate" span=".14572" stall_angle="181">
      <parent link="left_hand_wing"/>
  	<origin xyz="0 0 0" rpy="0 0 0"/> 
    </wing>
  </force_element>
<!--
  <force_element name="right_upper_wing_force"> 
    <wing chord=".08481" nominal_speed="1" profile="flat plate" span=".042" stall_angle="181">
      <parent link="right_upper_wing"/>
  	<origin xyz="0 0 0" rpy="0 0 0"/> 
    </wing>
  </force_element>
-->
  <force_element name="right_mid_wing_force"> 
    <wing chord=".13935" nominal_speed="1" profile="flat plate" span=".09296" stall_angle="181">
      <parent link="right_mid_wing"/>
  	<origin xyz="0 0 0" rpy="0 0 0"/> 
    </wing>
  </force_element>
  <force_element name="right_hand_wing_force"> 
    <wing chord=".11067" nominal_speed="1" profile="flat plate" span=".14572" stall_angle="181">
      <parent link="right_hand_wing"/>
  	<origin xyz="0 0 0" rpy="0 0 0"/> 
    </wing>
  </force_element>

  <force_element name="tail_spring">
    <torsional_spring stiffness="0.005" rest_angle="0">
      <joint name="tail_joint" />
    </torsional_spring>
  </force_element>

  <force_element name="left_shoulder_roll_spring">
    <torsional_spring stiffness="0.1" rest_angle="0">
      <joint name="left_shoulder_roll" />
    </torsional_spring>
  </force_element>

  <force_element name="left_shoulder_pitch_spring">
    <torsional_spring stiffness="0.1" rest_angle="0">
      <joint name="left_shoulder_pitch" />
    </torsional_spring>
  </force_element>

  <force_element name="left_shoulder_yaw_spring">
    <torsional_spring stiffness="0.1" rest_angle="0">
      <joint name="left_shoulder_yaw" />
    </torsional_spring>
  </force_element>

  <force_element name="left_elbow_roll_spring">
    <torsional_spring stiffness="0.05" rest_angle="0">
      <joint name="left_elbow_roll" />
    </torsional_spring>
  </force_element>

  <force_element name="left_elbow_pitch_spring">
    <torsional_spring stiffness="0.05" rest_angle="0">
      <joint name="left_elbow_pitch" />
    </torsional_spring>
  </force_element>

  <force_element name="left_elbow_yaw_spring">
    <torsional_spring stiffness="0.05" rest_angle="0">
      <joint name="left_elbow_yaw" />
    </torsional_spring>
  </force_element>

  <force_element name="left_wrist_roll_spring">
    <torsional_spring stiffness="0.005" rest_angle="0">
      <joint name="left_wrist_roll" />
    </torsional_spring>
  </force_element>

  <force_element name="right_shoulder_roll_spring">
    <torsional_spring stiffness="0.1" rest_angle="0">
      <joint name="right_shoulder_roll" />
    </torsional_spring>
  </force_element>

  <force_element name="right_shoulder_pitch_spring">
    <torsional_spring stiffness="0.1" rest_angle="0">
      <joint name="right_shoulder_pitch" />
    </torsional_spring>
  </force_element>

  <force_element name="right_shoulder_yaw_spring">
    <torsional_spring stiffness="0.1" rest_angle="0">
      <joint name="right_shoulder_yaw" />
    </torsional_spring>
  </force_element>

  <force_element name="right_elbow_roll_spring">
    <torsional_spring stiffness="0.05" rest_angle="0">
      <joint name="right_elbow_roll" />
    </torsional_spring>
  </force_element>

  <force_element name="right_elbow_pitch_spring">
    <torsional_spring stiffness="0.05" rest_angle="0">
      <joint name="right_elbow_pitch" />
    </torsional_spring>
  </force_element>

  <force_element name="right_elbow_pitch_spring">
    <torsional_spring stiffness="0.05" rest_angle="0">
      <joint name="right_elbow_yaw" />
    </torsional_spring>
  </force_element>

  <force_element name="right_wrist_roll_spring">
    <torsional_spring stiffness="0.005" rest_angle="0">
      <joint name="right_wrist_roll" />
    </torsional_spring>
  </force_element>

</robot>
