<robot
  name="pigeon_15">
  <link
    name="torso">
    <inertial>
      <origin
        xyz="-0.112665330319483 -4.6501440803508E-07 -0.0314957372746431"
        rpy="0 0 0" />
      <mass
        value="0.337792399438775" />
      <inertia
        ixx="0.000213744392058215"
        ixy="1.41607132067414E-08"
        ixz="4.48887348152591E-05"
        iyy="0.000899256138619334"
        iyz="-2.26830147050322E-09"
        izz="0.000883233595019567" />
    </inertial>
    <visual>
      <origin
        xyz="0 0 0"
        rpy="0 0 0" />
      <geometry>
        <mesh
          filename="package://pigeon_15/meshes/torso.STL" />
      </geometry>
      <material
        name="">
        <color
          rgba="0.792156862745098 0.819607843137255 0.933333333333333 1" />
      </material>
    </visual>
    <collision>
      <origin
        xyz="0 0 0"
        rpy="0 0 0" />
      <geometry>
        <mesh
          filename="package://pigeon_15/meshes/torso.STL" />
      </geometry>
    </collision>
  </link>
  <link
    name="tail_pitch_ghost">
    <inertial>
      <origin
        xyz="2.77555756156289E-17 5.35563050681133E-19 0"
        rpy="0 0 0" />
      <mass
        value="6.4E-11" />
      <inertia
        ixx="1.70666666666667E-14"
        ixy="-4.7621773422805E-31"
        ixz="2.22044604925031E-31"
        iyy="1.70666666666666E-14"
        iyz="1.06396373193244E-31"
        izz="1.70666666666666E-14" />
    </inertial>
    <visual>
      <origin
        xyz="0 0 0"
        rpy="0 0 0" />
      <geometry>
        <mesh
          filename="package://pigeon_15/meshes/tail_pitch_ghost.STL" />
      </geometry>
      <material
        name="">
        <color
          rgba="0.792156862745098 0.819607843137255 0.933333333333333 1" />
      </material>
    </visual>
    <collision>
      <origin
        xyz="0 0 0"
        rpy="0 0 0" />
      <geometry>
        <mesh
          filename="package://pigeon_15/meshes/tail_pitch_ghost.STL" />
      </geometry>
    </collision>
  </link>
  <joint
    name="tail_pitch"
    type="continuous">
    <origin
      xyz="-0.21 0 -0.0185680248036409"
      rpy="0 0 0" />
    <parent
      link="torso" />
    <child
      link="tail_pitch_ghost" />
    <axis
      xyz="0 -1 0" />
  </joint>
  <link
    name="tail">
    <inertial>
      <origin
        xyz="-0.0616510810483341 -1.67048220193117E-08 -5.75965664051381E-12"
        rpy="0 0 0" />
      <mass
        value="0.00272207360126705" />
      <inertia
        ixx="7.8032128545978E-06"
        ixy="6.26860530647084E-13"
        ixz="-3.52702359831784E-15"
        iyy="3.02804971213597E-06"
        iyz="7.5566652955272E-13"
        izz="1.08100978573672E-05" />
    </inertial>
    <visual>
      <origin
        xyz="0 0 0"
        rpy="0 0 0" />
      <geometry>
        <mesh
          filename="package://pigeon_15/meshes/tail.STL" />
      </geometry>
      <material
        name="">
        <color
          rgba="0.792156862745098 0.819607843137255 0.933333333333333 1" />
      </material>
    </visual>
    <collision>
      <origin
        xyz="0 0 0"
        rpy="0 0 0" />
      <geometry>
        <mesh
          filename="package://pigeon_15/meshes/tail.STL" />
      </geometry>
    </collision>
  </link>
  <joint
    name="tail_yaw"
    type="continuous">
    <origin
      xyz="0 0 0"
      rpy="0 0 0" />
    <parent
      link="tail_pitch_ghost" />
    <child
      link="tail" />
    <axis
      xyz="0 0 -1" />
  </joint>
  <link
    name="left_shoulder_roll_ghost">
    <inertial>
      <origin
        xyz="0 0 0"
        rpy="0 0 0" />
      <mass
        value="6.4E-11" />
      <inertia
        ixx="1.70666666666667E-14"
        ixy="-2.44017768954071E-31"
        ixz="2.22044604925031E-31"
        iyy="1.70666666666667E-14"
        iyz="1.06396373193244E-31"
        izz="1.70666666666667E-14" />
    </inertial>
    <visual>
      <origin
        xyz="0 0 0"
        rpy="0 0 0" />
      <geometry>
        <mesh
          filename="package://pigeon_15/meshes/left_shoulder_roll_ghost.STL" />
      </geometry>
      <material
        name="">
        <color
          rgba="0.792156862745098 0.819607843137255 0.933333333333333 1" />
      </material>
    </visual>
    <collision>
      <origin
        xyz="0 0 0"
        rpy="0 0 0" />
      <geometry>
        <mesh
          filename="package://pigeon_15/meshes/left_shoulder_roll_ghost.STL" />
      </geometry>
    </collision>
  </link>
  <joint
    name="left_shoulder_roll"
    type="continuous">
    <origin
      xyz="-0.08 0.0223499999999986 -0.0185680248036426"
      rpy="0 0 0" />
    <parent
      link="torso" />
    <child
      link="left_shoulder_roll_ghost" />
    <axis
      xyz="-1 0 0" />
  </joint>
  <link
    name="left_shoulder_pitch_ghost">
    <inertial>
      <origin
        xyz="1.38777878078145E-17 0 0"
        rpy="0 0 0" />
      <mass
        value="6.4E-11" />
      <inertia
        ixx="1.70666666666667E-14"
        ixy="-5.40077242187446E-31"
        ixz="2.22044604925031E-31"
        iyy="1.70666666666667E-14"
        iyz="-4.58292258309623E-31"
        izz="1.70666666666667E-14" />
    </inertial>
    <visual>
      <origin
        xyz="0 0 0"
        rpy="0 0 0" />
      <geometry>
        <mesh
          filename="package://pigeon_15/meshes/left_shoulder_pitch_ghost.STL" />
      </geometry>
      <material
        name="">
        <color
          rgba="0.792156862745098 0.819607843137255 0.933333333333333 1" />
      </material>
    </visual>
    <collision>
      <origin
        xyz="0 0 0"
        rpy="0 0 0" />
      <geometry>
        <mesh
          filename="package://pigeon_15/meshes/left_shoulder_pitch_ghost.STL" />
      </geometry>
    </collision>
  </link>
  <joint
    name="left_shoulder_pitch"
    type="continuous">
    <origin
      xyz="0 0 0"
      rpy="0 0 0" />
    <parent
      link="left_shoulder_roll_ghost" />
    <child
      link="left_shoulder_pitch_ghost" />
    <axis
      xyz="0 -1 0" />
  </joint>
  <link
    name="left_upper_wing">
    <inertial>
      <origin
        xyz="-0.0589528659250431 -0.0175535746761525 -7.49587544812691E-09"
        rpy="0 0 0" />
      <mass
        value="0.0061260000339972" />
      <inertia
        ixx="6.98406752630041E-07"
        ixy="-1.27189358154324E-07"
        ixz="2.3167583929233E-12"
        iyy="8.88423587527069E-06"
        iyz="2.73194876729002E-13"
        izz="9.39762886356476E-06" />
    </inertial>
    <visual>
      <origin
        xyz="0 0 0"
        rpy="0 0 0" />
      <geometry>
        <mesh
          filename="package://pigeon_15/meshes/left_upper_wing.STL" />
      </geometry>
      <material
        name="">
        <color
          rgba="0.843137254901961 0.862745098039216 0.980392156862745 1" />
      </material>
    </visual>
    <collision>
      <origin
        xyz="0 0 0"
        rpy="0 0 0" />
      <geometry>
        <mesh
          filename="package://pigeon_15/meshes/left_upper_wing.STL" />
      </geometry>
    </collision>
  </link>
  <joint
    name="left_shoulder_yaw"
    type="continuous">
    <origin
      xyz="0 0 0"
      rpy="3.14159265358979 0 0" />
    <parent
      link="left_shoulder_pitch_ghost" />
    <child
      link="left_upper_wing" />
    <axis
      xyz="0 0 -1" />
  </joint>
  <link
    name="left_mid_wing">
    <inertial>
      <origin
        xyz="-0.0309238874102576 -0.0478670898967761 4.70161401130986E-09"
        rpy="0 0 0" />
      <mass
        value="0.0118435988338924" />
      <inertia
        ixx="1.30936667015948E-05"
        ixy="3.30210259795655E-06"
        ixz="1.63589982484393E-13"
        iyy="1.60328428980403E-05"
        iyz="-1.13526713086094E-11"
        izz="2.88763216840842E-05" />
    </inertial>
    <visual>
      <origin
        xyz="0 0 0"
        rpy="0 0 0" />
      <geometry>
        <mesh
          filename="package://pigeon_15/meshes/left_mid_wing.STL" />
      </geometry>
      <material
        name="">
        <color
          rgba="0.843137254901961 0.862745098039216 0.980392156862745 1" />
      </material>
    </visual>
    <collision>
      <origin
        xyz="0 0 0"
        rpy="0 0 0" />
      <geometry>
        <mesh
          filename="package://pigeon_15/meshes/left_mid_wing.STL" />
      </geometry>
    </collision>
  </link>
  <joint
    name="left_elbow_yaw"
    type="continuous">
    <origin
      xyz="-0.024979991993594 -0.0349999999999973 0"
      rpy="0 0 0" />
    <parent
      link="left_upper_wing" />
    <child
      link="left_mid_wing" />
    <axis
      xyz="0 0 -1" />
  </joint>
  <link
    name="left_wrist_roll_ghost">
    <inertial>
      <origin
        xyz="6.93889390390723E-18 0 0"
        rpy="0 0 0" />
      <mass
        value="6.4E-11" />
      <inertia
        ixx="1.70666666666667E-14"
        ixy="-3.32371880805507E-46"
        ixz="2.22044604925031E-31"
        iyy="1.70666666666667E-14"
        iyz="2.22044604925031E-31"
        izz="1.70666666666667E-14" />
    </inertial>
    <visual>
      <origin
        xyz="0 0 0"
        rpy="0 0 0" />
      <geometry>
        <mesh
          filename="package://pigeon_15/meshes/left_wrist_roll_ghost.STL" />
      </geometry>
      <material
        name="">
        <color
          rgba="0.792156862745098 0.819607843137255 0.933333333333333 1" />
      </material>
    </visual>
    <collision>
      <origin
        xyz="0 0 0"
        rpy="0 0 0" />
      <geometry>
        <mesh
          filename="package://pigeon_15/meshes/left_wrist_roll_ghost.STL" />
      </geometry>
    </collision>
  </link>
  <joint
    name="left_wrist_roll"
    type="continuous">
    <origin
      xyz="0.0519142912418165 -0.0349999999999929 0"
      rpy="0 0 0" />
    <parent
      link="left_mid_wing" />
    <child
      link="left_wrist_roll_ghost" />
    <axis
      xyz="-1 0 0" />
  </joint>
  <link
    name="left_wrist_pitch_ghost">
    <inertial>
      <origin
        xyz="6.93889390390723E-18 0 -3.46944695195361E-18"
        rpy="0 0 0" />
      <mass
        value="6.4E-11" />
      <inertia
        ixx="1.70666666666667E-14"
        ixy="-3.29306540414796E-46"
        ixz="2.22044604925031E-31"
        iyy="1.70666666666667E-14"
        iyz="2.22044604925031E-31"
        izz="1.70666666666667E-14" />
    </inertial>
    <visual>
      <origin
        xyz="0 0 0"
        rpy="0 0 0" />
      <geometry>
        <mesh
          filename="package://pigeon_15/meshes/left_wrist_pitch_ghost.STL" />
      </geometry>
      <material
        name="">
        <color
          rgba="0.792156862745098 0.819607843137255 0.933333333333333 1" />
      </material>
    </visual>
    <collision>
      <origin
        xyz="0 0 0"
        rpy="0 0 0" />
      <geometry>
        <mesh
          filename="package://pigeon_15/meshes/left_wrist_pitch_ghost.STL" />
      </geometry>
    </collision>
  </link>
  <joint
    name="left_wrist_pitch"
    type="continuous">
    <origin
      xyz="0 0 0"
      rpy="0 0 0" />
    <parent
      link="left_wrist_roll_ghost" />
    <child
      link="left_wrist_pitch_ghost" />
    <axis
      xyz="0 -1 0" />
  </joint>
  <link
    name="left_hand_wing">
    <inertial>
      <origin
        xyz="-0.0496305425022118 -0.114426970261576 -1.63178679839227E-06"
        rpy="0 0 0" />
      <mass
        value="0.00775959953779964" />
      <inertia
        ixx="2.04444761571872E-05"
        ixy="5.05536086513189E-06"
        ixz="-5.97859087313011E-10"
        iyy="6.83432712985513E-06"
        iyz="-1.22871287544933E-09"
        izz="2.72012939551031E-05" />
    </inertial>
    <visual>
      <origin
        xyz="0 0 0"
        rpy="0 0 0" />
      <geometry>
        <mesh
          filename="package://pigeon_15/meshes/left_hand_wing.STL" />
      </geometry>
      <material
        name="">
        <color
          rgba="0.843137254901961 0.862745098039216 0.980392156862745 1" />
      </material>
    </visual>
    <collision>
      <origin
        xyz="0 0 0"
        rpy="0 0 0" />
      <geometry>
        <mesh
          filename="package://pigeon_15/meshes/left_hand_wing.STL" />
      </geometry>
    </collision>
  </link>
  <joint
    name="left_wrist_yaw"
    type="continuous">
    <origin
      xyz="0 0 0"
      rpy="0 0 0" />
    <parent
      link="left_wrist_pitch_ghost" />
    <child
      link="left_hand_wing" />
    <axis
      xyz="0 0 -1" />
  </joint>
  <link
    name="right_shoulder_roll_ghost">
    <inertial>
      <origin
        xyz="1.38777878078145E-17 0 0"
        rpy="0 0 0" />
      <mass
        value="6.4E-11" />
      <inertia
        ixx="1.70666666666667E-14"
        ixy="4.78047734045658E-31"
        ixz="1.507489055057E-30"
        iyy="1.70666666666667E-14"
        iyz="-8.98174356683639E-31"
        izz="1.70666666666667E-14" />
    </inertial>
    <visual>
      <origin
        xyz="0 0 0"
        rpy="0 0 0" />
      <geometry>
        <mesh
          filename="package://pigeon_15/meshes/right_shoulder_roll_ghost.STL" />
      </geometry>
      <material
        name="">
        <color
          rgba="0.792156862745098 0.819607843137255 0.933333333333333 1" />
      </material>
    </visual>
    <collision>
      <origin
        xyz="0 0 0"
        rpy="0 0 0" />
      <geometry>
        <mesh
          filename="package://pigeon_15/meshes/right_shoulder_roll_ghost.STL" />
      </geometry>
    </collision>
  </link>
  <joint
    name="right_shoulder_roll"
    type="continuous">
    <origin
      xyz="-0.08 -0.02235 -0.0185680248036409"
      rpy="-1.05554753939627E-07 0 0" />
    <parent
      link="torso" />
    <child
      link="right_shoulder_roll_ghost" />
    <axis
      xyz="-1 0 0" />
  </joint>
  <link
    name="right_shoulder_pitch_ghost">
    <inertial>
      <origin
        xyz="0 0 6.93889390390723E-18"
        rpy="0 0 0" />
      <mass
        value="6.4E-11" />
      <inertia
        ixx="1.70666666666667E-14"
        ixy="1.57980039864423E-30"
        ixz="-1.05489841054092E-30"
        iyy="1.70666666666667E-14"
        iyz="-7.5994148724163E-31"
        izz="1.70666666666667E-14" />
    </inertial>
    <visual>
      <origin
        xyz="0 0 0"
        rpy="0 0 0" />
      <geometry>
        <mesh
          filename="package://pigeon_15/meshes/right_shoulder_pitch_ghost.STL" />
      </geometry>
      <material
        name="">
        <color
          rgba="0.792156862745098 0.819607843137255 0.933333333333333 1" />
      </material>
    </visual>
    <collision>
      <origin
        xyz="0 0 0"
        rpy="0 0 0" />
      <geometry>
        <mesh
          filename="package://pigeon_15/meshes/right_shoulder_pitch_ghost.STL" />
      </geometry>
    </collision>
  </link>
  <joint
    name="right_shoulder_pitch"
    type="continuous">
    <origin
      xyz="0 0 0"
      rpy="2.0291111002841E-17 2.74327909829207E-07 1.79851477442537E-15" />
    <parent
      link="right_shoulder_roll_ghost" />
    <child
      link="right_shoulder_pitch_ghost" />
    <axis
      xyz="0 -0.999999999999989 0" />
  </joint>
  <link
    name="right_upper_wing">
    <inertial>
      <origin
        xyz="-0.0589528659250257 -0.0175535746761505 -7.49587509771277E-09"
        rpy="0 0 0" />
      <mass
        value="0.00612600003399489" />
      <inertia
        ixx="6.98406752630195E-07"
        ixy="-1.27189358155062E-07"
        ixz="2.31675834965555E-12"
        iyy="8.88423587526524E-06"
        iyz="2.73194499883439E-13"
        izz="9.39762886355896E-06" />
    </inertial>
    <visual>
      <origin
        xyz="0 0 0"
        rpy="0 0 0" />
      <geometry>
        <mesh
          filename="package://pigeon_15/meshes/right_upper_wing.STL" />
      </geometry>
      <material
        name="">
        <color
          rgba="0.843137254901961 0.862745098039216 0.980392156862745 1" />
      </material>
    </visual>
    <collision>
      <origin
        xyz="0 0 0"
        rpy="0 0 0" />
      <geometry>
        <mesh
          filename="package://pigeon_15/meshes/right_upper_wing.STL" />
      </geometry>
    </collision>
  </link>
  <joint
    name="right_shoulder_yaw"
    type="continuous">
    <origin
      xyz="0 0 0"
      rpy="1.40686878583019E-18 -3.10627098790649E-17 -2.97269970499519E-14" />
    <parent
      link="right_shoulder_pitch_ghost" />
    <child
      link="right_upper_wing" />
    <axis
      xyz="0.999999999999925 0 0" />
  </joint>
  <link
    name="right_mid_wing">
    <inertial>
      <origin
        xyz="-0.0309238874102866 -0.0478670898968001 4.701626199477E-09"
        rpy="0 0 0" />
      <mass
        value="0.0118435988338867" />
      <inertia
        ixx="1.30936667016344E-05"
        ixy="3.30210259797076E-06"
        ixz="1.6358311118034E-13"
        iyy="1.60328428981203E-05"
        iyz="-1.13526918293621E-11"
        izz="2.88763216842036E-05" />
    </inertial>
    <visual>
      <origin
        xyz="0 0 0"
        rpy="0 0 0" />
      <geometry>
        <mesh
          filename="package://pigeon_15/meshes/right_mid_wing.STL" />
      </geometry>
      <material
        name="">
        <color
          rgba="0.843137254901961 0.862745098039216 0.980392156862745 1" />
      </material>
    </visual>
    <collision>
      <origin
        xyz="0 0 0"
        rpy="0 0 0" />
      <geometry>
        <mesh
          filename="package://pigeon_15/meshes/right_mid_wing.STL" />
      </geometry>
    </collision>
  </link>
  <joint
    name="right_elbow_yaw"
    type="continuous">
    <origin
      xyz="-0.0249799919935937 -0.0350000000000001 0"
      rpy="-4.7636921195345E-17 -1.86542065973815E-17 3.21998553575834E-14" />
    <parent
      link="right_upper_wing" />
    <child
      link="right_mid_wing" />
    <axis
      xyz="0 0 -0.999999999999914" />
  </joint>
  <link
    name="right_wrist_roll_ghost">
    <inertial>
      <origin
        xyz="0 0 3.46944695195361E-18"
        rpy="0 0 0" />
      <mass
        value="6.4E-11" />
      <inertia
        ixx="1.70666666666667E-14"
        ixy="2.22360867419039E-30"
        ixz="7.43084710171742E-31"
        iyy="1.70666666666667E-14"
        iyz="1.84200498342017E-31"
        izz="1.70666666666667E-14" />
    </inertial>
    <visual>
      <origin
        xyz="0 0 0"
        rpy="0 0 0" />
      <geometry>
        <mesh
          filename="package://pigeon_15/meshes/right_wrist_roll_ghost.STL" />
      </geometry>
      <material
        name="">
        <color
          rgba="0.792156862745098 0.819607843137255 0.933333333333333 1" />
      </material>
    </visual>
    <collision>
      <origin
        xyz="0 0 0"
        rpy="0 0 0" />
      <geometry>
        <mesh
          filename="package://pigeon_15/meshes/right_wrist_roll_ghost.STL" />
      </geometry>
    </collision>
  </link>
  <joint
    name="right_wrist_roll"
    type="continuous">
    <origin
      xyz="0.0519142912418186 -0.034999999999993 0"
      rpy="1.05554753965563E-07 -1.43731962028398E-17 2.46852419319722E-14" />
    <parent
      link="right_mid_wing" />
    <child
      link="right_wrist_roll_ghost" />
    <axis
      xyz="-0.999999999999925 0 0" />
  </joint>
  <link
    name="right_wrist_pitch_ghost">
    <inertial>
      <origin
        xyz="6.93889390390723E-18 0 0"
        rpy="0 0 0" />
      <mass
        value="6.4E-11" />
      <inertia
        ixx="1.70666666666667E-14"
        ixy="3.15033011251872E-31"
        ixz="2.22044604925031E-31"
        iyy="1.70666666666667E-14"
        iyz="-9.07332658080703E-31"
        izz="1.70666666666667E-14" />
    </inertial>
    <visual>
      <origin
        xyz="0 0 0"
        rpy="0 0 0" />
      <geometry>
        <mesh
          filename="package://pigeon_15/meshes/right_wrist_pitch_ghost.STL" />
      </geometry>
      <material
        name="">
        <color
          rgba="0.792156862745098 0.819607843137255 0.933333333333333 1" />
      </material>
    </visual>
    <collision>
      <origin
        xyz="0 0 0"
        rpy="0 0 0" />
      <geometry>
        <mesh
          filename="package://pigeon_15/meshes/right_wrist_pitch_ghost.STL" />
      </geometry>
    </collision>
  </link>
  <joint
    name="right_wrist_pitch"
    type="continuous">
    <origin
      xyz="0 0 0"
      rpy="0 -2.74327909765118E-07 0" />
    <parent
      link="right_wrist_roll_ghost" />
    <child
      link="right_wrist_pitch_ghost" />
    <axis
      xyz="0 -1 0" />
  </joint>
  <link
    name="right_hand_wing">
    <inertial>
      <origin
        xyz="-0.0496305425022117 -0.114426970261576 -1.63178679839227E-06"
        rpy="0 0 0" />
      <mass
        value="0.00775959953779963" />
      <inertia
        ixx="2.04444761571871E-05"
        ixy="5.05536086513198E-06"
        ixz="-5.97859087319426E-10"
        iyy="6.83432712985444E-06"
        iyz="-1.22871287545199E-09"
        izz="2.72012939551023E-05" />
    </inertial>
    <visual>
      <origin
        xyz="0 0 0"
        rpy="0 0 0" />
      <geometry>
        <mesh
          filename="package://pigeon_15/meshes/right_hand_wing.STL" />
      </geometry>
      <material
        name="">
        <color
          rgba="0.843137254901961 0.862745098039216 0.980392156862745 1" />
      </material>
    </visual>
    <collision>
      <origin
        xyz="0 0 0"
        rpy="0 0 0" />
      <geometry>
        <mesh
          filename="package://pigeon_15/meshes/right_hand_wing.STL" />
      </geometry>
    </collision>
  </link>
  <joint
    name="right_wrist_yaw"
    type="continuous">
    <origin
      xyz="0 0 0"
      rpy="0 0 0" />
    <parent
      link="right_wrist_pitch_ghost" />
    <child
      link="right_hand_wing" />
    <axis
      xyz="0 0 -1" />
  </joint>
  <link
    name="left_hip_roll_ghost">
    <inertial>
      <origin
        xyz="0 0 6.93889390390723E-18"
        rpy="0 0 0" />
      <mass
        value="6.4E-11" />
      <inertia
        ixx="1.70666666666667E-14"
        ixy="-4.90673763194523E-31"
        ixz="2.2204460492503E-31"
        iyy="1.70666666666667E-14"
        iyz="2.22044604925031E-31"
        izz="1.70666666666667E-14" />
    </inertial>
    <visual>
      <origin
        xyz="0 0 0"
        rpy="0 0 0" />
      <geometry>
        <mesh
          filename="package://pigeon_15/meshes/left_hip_roll_ghost.STL" />
      </geometry>
      <material
        name="">
        <color
          rgba="0.792156862745098 0.819607843137255 0.933333333333333 1" />
      </material>
    </visual>
    <collision>
      <origin
        xyz="0 0 0"
        rpy="0 0 0" />
      <geometry>
        <mesh
          filename="package://pigeon_15/meshes/left_hip_roll_ghost.STL" />
      </geometry>
    </collision>
  </link>
  <joint
    name="left_hip_roll"
    type="continuous">
    <origin
      xyz="-0.13 0.02235 -0.05"
      rpy="0 0 0" />
    <parent
      link="torso" />
    <child
      link="left_hip_roll_ghost" />
    <axis
      xyz="-1 0 0" />
  </joint>
  <link
    name="left_upper_leg">
    <inertial>
      <origin
        xyz="-0.00815178843284745 -8.462841218429E-08 -0.00646288978903064"
        rpy="0 0 0" />
      <mass
        value="0.0111185075943755" />
      <inertia
        ixx="1.30194564513326E-06"
        ixy="-8.08321033905005E-13"
        ixz="4.78322446038763E-07"
        iyy="1.90527331601825E-06"
        iyz="3.79888864598512E-12"
        izz="1.52601541753993E-06" />
    </inertial>
    <visual>
      <origin
        xyz="0 0 0"
        rpy="0 0 0" />
      <geometry>
        <mesh
          filename="package://pigeon_15/meshes/left_upper_leg.STL" />
      </geometry>
      <material
        name="">
        <color
          rgba="0.792156862745098 0.819607843137255 0.933333333333333 1" />
      </material>
    </visual>
    <collision>
      <origin
        xyz="0 0 0"
        rpy="0 0 0" />
      <geometry>
        <mesh
          filename="package://pigeon_15/meshes/left_upper_leg.STL" />
      </geometry>
    </collision>
  </link>
  <joint
    name="left_hip_pitch"
    type="continuous">
    <origin
      xyz="0 0.000717593139346714 0"
      rpy="0 0 0" />
    <parent
      link="left_hip_roll_ghost" />
    <child
      link="left_upper_leg" />
    <axis
      xyz="0 -1 0" />
  </joint>
  <link
    name="left_mid_leg">
    <inertial>
      <origin
        xyz="-0.0152500256210223 5.7470192202369E-08 0.00698108705383533"
        rpy="0 0 0" />
      <mass
        value="0.00669510293187008" />
      <inertia
        ixx="5.04510496105422E-07"
        ixy="4.96966831066946E-12"
        ixz="-5.56940527787755E-07"
        iyy="1.7210564263055E-06"
        iyz="-6.99112799237926E-12"
        izz="1.46605012945107E-06" />
    </inertial>
    <visual>
      <origin
        xyz="0 0 0"
        rpy="0 0 0" />
      <geometry>
        <mesh
          filename="package://pigeon_15/meshes/left_mid_leg.STL" />
      </geometry>
      <material
        name="">
        <color
          rgba="0.792156862745098 0.819607843137255 0.933333333333333 1" />
      </material>
    </visual>
    <collision>
      <origin
        xyz="0 0 0"
        rpy="0 0 0" />
      <geometry>
        <mesh
          filename="package://pigeon_15/meshes/left_mid_leg.STL" />
      </geometry>
    </collision>
  </link>
  <joint
    name="left_knee_pitch"
    type="continuous">
    <origin
      xyz="-0.0230177507128035 0 -0.0182484917613644"
      rpy="0 0 0" />
    <parent
      link="left_upper_leg" />
    <child
      link="left_mid_leg" />
    <axis
      xyz="0 -1 0" />
  </joint>
  <link
    name="left_lower_leg">
    <inertial>
      <origin
        xyz="-0.00764464432377804 3.15556022284502E-10 -0.00295454755610564"
        rpy="0 0 0" />
      <mass
        value="0.00133046127997812" />
      <inertia
        ixx="2.93575970112394E-08"
        ixy="1.06392271594589E-14"
        ixz="2.80950375988377E-08"
        iyy="1.02051114118785E-07"
        iyz="4.10335342148623E-15"
        izz="9.11927713295393E-08" />
    </inertial>
    <visual>
      <origin
        xyz="0 0 0"
        rpy="0 0 0" />
      <geometry>
        <mesh
          filename="package://pigeon_15/meshes/left_lower_leg.STL" />
      </geometry>
      <material
        name="">
        <color
          rgba="0.792156862745098 0.819607843137255 0.933333333333333 1" />
      </material>
    </visual>
    <collision>
      <origin
        xyz="0 0 0"
        rpy="0 0 0" />
      <geometry>
        <mesh
          filename="package://pigeon_15/meshes/left_lower_leg.STL" />
      </geometry>
    </collision>
  </link>
  <joint
    name="left_ankle_pitch"
    type="continuous">
    <origin
      xyz="-0.0398619536347535 0 0.0182484917613644"
      rpy="0 0 0" />
    <parent
      link="left_mid_leg" />
    <child
      link="left_lower_leg" />
    <axis
      xyz="0 -1 0" />
  </joint>
  <link
    name="left_thumb">
    <inertial>
      <origin
        xyz="-0.00560443346870271 3.09317174859713E-07 0.00542363339667958"
        rpy="0 0 0" />
      <mass
        value="0.000250796091698898" />
      <inertia
        ixx="4.73568286284379E-09"
        ixy="3.07047738324149E-13"
        ixz="-4.76448520988393E-09"
        iyy="1.17600371917558E-08"
        iyz="1.29549580008467E-13"
        izz="7.83263044452895E-09" />
    </inertial>
    <visual>
      <origin
        xyz="0 0 0"
        rpy="0 0 0" />
      <geometry>
        <mesh
          filename="package://pigeon_15/meshes/left_thumb.STL" />
      </geometry>
      <material
        name="">
        <color
          rgba="0.792156862745098 0.819607843137255 0.933333333333333 1" />
      </material>
    </visual>
    <collision>
      <origin
        xyz="0 0 0"
        rpy="0 0 0" />
      <geometry>
        <mesh
          filename="package://pigeon_15/meshes/left_thumb.STL" />
      </geometry>
    </collision>
  </link>
  <joint
    name="left_thumb_pitch"
    type="continuous">
    <origin
      xyz="-0.0225594445140304 0 -0.0087189116816682"
      rpy="0 0 0" />
    <parent
      link="left_lower_leg" />
    <child
      link="left_thumb" />
    <axis
      xyz="0 -1 0" />
  </joint>
  <link
    name="left_fingers">
    <inertial>
      <origin
        xyz="-0.0143087077723983 -8.69364821183896E-06 0.0013377940764445"
        rpy="0 0 0" />
      <mass
        value="0.00104625896848744" />
      <inertia
        ixx="5.53108395886291E-08"
        ixy="9.01489697131554E-11"
        ixz="-1.93623681673225E-08"
        iyy="8.1133372745836E-08"
        iyz="-4.381635736265E-11"
        izz="1.1785773089308E-07" />
    </inertial>
    <visual>
      <origin
        xyz="0 0 0"
        rpy="0 0 0" />
      <geometry>
        <mesh
          filename="package://pigeon_15/meshes/left_fingers.STL" />
      </geometry>
      <material
        name="">
        <color
          rgba="0.792156862745098 0.819607843137255 0.933333333333333 1" />
      </material>
    </visual>
    <collision>
      <origin
        xyz="0 0 0"
        rpy="0 0 0" />
      <geometry>
        <mesh
          filename="package://pigeon_15/meshes/left_fingers.STL" />
      </geometry>
    </collision>
  </link>
  <joint
    name="left_fingers_pitch"
    type="continuous">
    <origin
      xyz="-0.0225594445140304 0 -0.0087189116816682"
      rpy="0 0 0" />
    <parent
      link="left_lower_leg" />
    <child
      link="left_fingers" />
    <axis
      xyz="0 -1 0" />
  </joint>
  <link
    name="right_hip_roll_ghost">
    <inertial>
      <origin
        xyz="0 0 6.93889390390723E-18"
        rpy="0 0 0" />
      <mass
        value="6.4E-11" />
      <inertia
        ixx="1.70666666666667E-14"
        ixy="5.64688631502867E-31"
        ixz="2.22044604925031E-31"
        iyy="1.70666666666667E-14"
        iyz="2.22044604925031E-31"
        izz="1.70666666666667E-14" />
    </inertial>
    <visual>
      <origin
        xyz="0 0 0"
        rpy="0 0 0" />
      <geometry>
        <mesh
          filename="package://pigeon_15/meshes/right_hip_roll_ghost.STL" />
      </geometry>
      <material
        name="">
        <color
          rgba="0.792156862745098 0.819607843137255 0.933333333333333 1" />
      </material>
    </visual>
    <collision>
      <origin
        xyz="0 0 0"
        rpy="0 0 0" />
      <geometry>
        <mesh
          filename="package://pigeon_15/meshes/right_hip_roll_ghost.STL" />
      </geometry>
    </collision>
  </link>
  <joint
    name="right_hip_roll"
    type="continuous">
    <origin
      xyz="-0.13 -0.02235 -0.05"
      rpy="0 0 0" />
    <parent
      link="torso" />
    <child
      link="right_hip_roll_ghost" />
    <axis
      xyz="-1 0 0" />
  </joint>
  <link
    name="right_upper_leg">
    <inertial>
      <origin
        xyz="-0.00815178843284745 -8.46284121738816E-08 -0.00646288978903063"
        rpy="0 0 0" />
      <mass
        value="0.0111185075943756" />
      <inertia
        ixx="1.30194564513326E-06"
        ixy="-8.08321033352887E-13"
        ixz="4.78322446038763E-07"
        iyy="1.90527331601825E-06"
        iyz="3.79888864648503E-12"
        izz="1.52601541753994E-06" />
    </inertial>
    <visual>
      <origin
        xyz="0 0 0"
        rpy="0 0 0" />
      <geometry>
        <mesh
          filename="package://pigeon_15/meshes/right_upper_leg.STL" />
      </geometry>
      <material
        name="">
        <color
          rgba="0.792156862745098 0.819607843137255 0.933333333333333 1" />
      </material>
    </visual>
    <collision>
      <origin
        xyz="0 0 0"
        rpy="0 0 0" />
      <geometry>
        <mesh
          filename="package://pigeon_15/meshes/right_upper_leg.STL" />
      </geometry>
    </collision>
  </link>
  <joint
    name="right_hip_pitch"
    type="continuous">
    <origin
      xyz="0 0.000717593139346714 0"
      rpy="0 0 0" />
    <parent
      link="right_hip_roll_ghost" />
    <child
      link="right_upper_leg" />
    <axis
      xyz="0 -1 0" />
  </joint>
  <link
    name="right_mid_leg">
    <inertial>
      <origin
        xyz="-0.0152500256210223 5.74701921988996E-08 0.00698108705383532"
        rpy="0 0 0" />
      <mass
        value="0.00669510293187009" />
      <inertia
        ixx="5.04510496105423E-07"
        ixy="4.96966831090515E-12"
        ixz="-5.56940527787755E-07"
        iyy="1.7210564263055E-06"
        iyz="-6.99112799254089E-12"
        izz="1.46605012945107E-06" />
    </inertial>
    <visual>
      <origin
        xyz="0 0 0"
        rpy="0 0 0" />
      <geometry>
        <mesh
          filename="package://pigeon_15/meshes/right_mid_leg.STL" />
      </geometry>
      <material
        name="">
        <color
          rgba="0.792156862745098 0.819607843137255 0.933333333333333 1" />
      </material>
    </visual>
    <collision>
      <origin
        xyz="0 0 0"
        rpy="0 0 0" />
      <geometry>
        <mesh
          filename="package://pigeon_15/meshes/right_mid_leg.STL" />
      </geometry>
    </collision>
  </link>
  <joint
    name="right_knee_pitch"
    type="continuous">
    <origin
      xyz="-0.0230177507128035 0 -0.0182484917613644"
      rpy="0 0 0" />
    <parent
      link="right_upper_leg" />
    <child
      link="right_mid_leg" />
    <axis
      xyz="0 -1 0" />
  </joint>
  <link
    name="right_lower_leg">
    <inertial>
      <origin
        xyz="-0.00764464432377804 3.15556022284502E-10 -0.00295454755610564"
        rpy="0 0 0" />
      <mass
        value="0.00133046127997812" />
      <inertia
        ixx="2.93575970112394E-08"
        ixy="1.06392271594589E-14"
        ixz="2.80950375988377E-08"
        iyy="1.02051114118785E-07"
        iyz="4.10335342148623E-15"
        izz="9.11927713295393E-08" />
    </inertial>
    <visual>
      <origin
        xyz="0 0 0"
        rpy="0 0 0" />
      <geometry>
        <mesh
          filename="package://pigeon_15/meshes/right_lower_leg.STL" />
      </geometry>
      <material
        name="">
        <color
          rgba="0.792156862745098 0.819607843137255 0.933333333333333 1" />
      </material>
    </visual>
    <collision>
      <origin
        xyz="0 0 0"
        rpy="0 0 0" />
      <geometry>
        <mesh
          filename="package://pigeon_15/meshes/right_lower_leg.STL" />
      </geometry>
    </collision>
  </link>
  <joint
    name="right_ankle_pitch"
    type="continuous">
    <origin
      xyz="-0.0398619536347535 0 0.0182484917613644"
      rpy="0 0 0" />
    <parent
      link="right_mid_leg" />
    <child
      link="right_lower_leg" />
    <axis
      xyz="0 -1 0" />
  </joint>
  <link
    name="right_thumb">
    <inertial>
      <origin
        xyz="-0.00560443346870271 3.09317174852775E-07 0.0054236333966796"
        rpy="0 0 0" />
      <mass
        value="0.000250796091698898" />
      <inertia
        ixx="4.73568286284379E-09"
        ixy="3.07047738317106E-13"
        ixz="-4.76448520988395E-09"
        iyy="1.17600371917559E-08"
        iyz="1.29549580015495E-13"
        izz="7.83263044452901E-09" />
    </inertial>
    <visual>
      <origin
        xyz="0 0 0"
        rpy="0 0 0" />
      <geometry>
        <mesh
          filename="package://pigeon_15/meshes/right_thumb.STL" />
      </geometry>
      <material
        name="">
        <color
          rgba="0.792156862745098 0.819607843137255 0.933333333333333 1" />
      </material>
    </visual>
    <collision>
      <origin
        xyz="0 0 0"
        rpy="0 0 0" />
      <geometry>
        <mesh
          filename="package://pigeon_15/meshes/right_thumb.STL" />
      </geometry>
    </collision>
  </link>
  <joint
    name="right_thumb_pitch"
    type="continuous">
    <origin
      xyz="-0.0225594445140304 0 -0.0087189116816682"
      rpy="0 0 0" />
    <parent
      link="right_lower_leg" />
    <child
      link="right_thumb" />
    <axis
      xyz="0 -1 0" />
  </joint>
  <link
    name="right_fingers">
    <inertial>
      <origin
        xyz="-0.0143087077723983 -8.69364821194998E-06 0.00133779407644451"
        rpy="0 0 0" />
      <mass
        value="0.00104625896848745" />
      <inertia
        ixx="5.53108395886295E-08"
        ixy="9.01489697138834E-11"
        ixz="-1.93623681673226E-08"
        iyy="8.1133372745837E-08"
        iyz="-4.38163573631296E-11"
        izz="1.17857730893081E-07" />
    </inertial>
    <visual>
      <origin
        xyz="0 0 0"
        rpy="0 0 0" />
      <geometry>
        <mesh
          filename="package://pigeon_15/meshes/right_fingers.STL" />
      </geometry>
      <material
        name="">
        <color
          rgba="0.792156862745098 0.819607843137255 0.933333333333333 1" />
      </material>
    </visual>
    <collision>
      <origin
        xyz="0 0 0"
        rpy="0 0 0" />
      <geometry>
        <mesh
          filename="package://pigeon_15/meshes/right_fingers.STL" />
      </geometry>
    </collision>
  </link>
  <joint
    name="right_fingers_pitch"
    type="continuous">
    <origin
      xyz="-0.0225594445140304 0 -0.0087189116816682"
      rpy="0 0 0" />
    <parent
      link="right_lower_leg" />
    <child
      link="right_fingers" />
    <axis
      xyz="0 -1 0" />
  </joint>
</robot>