<?xml version="1.0"?>

<robot
  name="pigeon_flat_plate_with_ballsocket">





  <link
    name="torso">
    <inertial>
      <origin
        xyz="-0.0629726051612279 -0.0795364123806518 -0.0718210124188262"
        rpy="0 0 0" />
      <mass
        value="0.671119349684871" />
      <inertia
        ixx="0.00202085553857623"
        ixy="-1.51403317046805E-08"
        ixz="-5.76561128003562E-07"
        iyy="0.0021573468866358"
        iyz="-3.77085085679846E-05"
        izz="0.000411519567288276" />
    </inertial>
    <visual>
      <origin
        xyz="0 0 0"
        rpy="0 0 0" />
      <geometry>
        <mesh
          filename="../meshes/torso.STL" />
      </geometry>
      <material
        name="">
        <color
          rgba="0.5 0.5 0.5" />
      </material>
    </visual>
  </link>


  <link
    name="tail">
    <inertial>
      <origin
        xyz="-0.062961900175268 0 0.0652517307094301"
        rpy="0 0 0" />
      <mass
        value="0.0785082730854115" />
      <inertia
        ixx="6.49970704865375E-05"
        ixy="-4.9113848870336E-22"
        ixz="9.18897553043541E-21"
        iyy="0.000317828010500285"
        iyz="5.56269610365498E-23"
        izz="0.00025303784461276" />
    </inertial>
    <visual>
      <origin
        xyz="0 0 0"
        rpy="0 0 0" />
      <geometry>
        <mesh
          filename="../meshes/tail.STL" />
      </geometry>
      <material
        name="">
        <color
          rgba="0.5 0.5 0.5" />
      </material>
    </visual>
  </link>

  <link
    name="ls_ghost_one">
    <inertial>
      <mass
        value="0" />
    </inertial>
  </link>

  <link
    name="ls_ghost_two">
    <inertial>
      <mass
        value="0" />
    </inertial>
  </link>

  <link
    name="left_upper_wing">
    <inertial>
      <origin

        xyz="-0.0218027728742861 0.00425638927508182 0.0543039239207449"
        rpy="0 0 0" />
      <mass
        value="0.0145874370217867" />
      <inertia
        ixx="1.06020581310142E-05"

        ixy="-4.36971336865206E-12"
        ixz="-1.34725553735654E-06"
        iyy="1.26551908630607E-05"
        iyz="-1.00029622741659E-11"
        izz="2.0908636076509E-06" />
    </inertial>
    <visual>
      <origin
        xyz="0 0 0"
        rpy="0 0 0" />
      <geometry>
        <mesh
          filename="../meshes/left_upper_wing.STL" />
      </geometry>
      <material
        name="">
        <color

          rgba="0.5 0.5 0.5" />
      </material>
    </visual>
  </link>

  <link
    name="le_ghost_one">
    <inertial>
      <mass
        value="0" />
    </inertial>
  </link>

  <link
    name="le_ghost_two">
    <inertial>
      <mass
        value="0" />
    </inertial>
  </link>

  <link
    name="left_mid_wing">
    <inertial>
      <origin

        xyz="-0.0461463515315644 7.03928810380505E-08 0.0495486671552646"
        rpy="0 0 0" />
      <mass
        value="0.0435482141171192" />
      <inertia
        ixx="5.33772461233848E-05"

        ixy="-1.02931259410496E-10"
        ixz="7.79267317879271E-06"
        iyy="8.30778126011954E-05"
        iyz="5.19612845243408E-12"
        izz="2.98149493682923E-05" />
    </inertial>
    <visual>
      <origin
        xyz="0 0 0"
        rpy="0 0 0" />
      <geometry>
        <mesh

          filename="../meshes/left_mid_wing.STL" />
      </geometry>
      <material

        name="">
        <color
          rgba="0.5 0.5 0.5" />
      </material>
    </visual>
  </link>

  <link
    name="left_hand_wing">
    <inertial>
      <origin
        xyz="-0.0597835085302464 3.75240510469554E-08 0.0458134593577523"
        rpy="0 0 0" />
      <mass
        value="0.0455297796070339" />
      <inertia

        ixx="3.23421498648179E-05"
        ixy="-5.57963540896952E-11"
        ixz="-1.17630180635893E-05"
        iyy="0.000100020749222614"
        iyz="3.58722193014884E-12"
        izz="6.77981793917095E-05" />
    </inertial>
    <visual>
      <origin
        xyz="0 0 0"
        rpy="0 0 0" />
      <geometry>
        <mesh
          filename="../meshes/left_hand_wing.STL" />
      </geometry>
      <material
        name="">
        <color
          rgba="0.5 0.5 0.5" />
      </material>
    </visual>
  </link>

  <link
    name="rs_ghost_two">
    <inertial>
      <mass

        value="0" />
    </inertial>
  </link>

  <link
    name="rs_ghost_one">
    <inertial>
      <mass
        value="0" />
    </inertial>
  </link>

  <link
    name="right_upper_wing">
    <inertial>
      <origin

        xyz="-0.0218027728742861 -0.00425641457903929 0.0543039239207449"
        rpy="0 0 0" />
      <mass
        value="0.0145874370217868" />
      <inertia
        ixx="1.06020581310143E-05"

        ixy="-4.36971336818353E-12"
        ixz="-1.34725553735654E-06"

        iyy="1.26551908630607E-05"

        iyz="-1.00029622740166E-11"
        izz="2.09086360765091E-06" />
    </inertial>
    <visual>
      <origin
        xyz="0 0 0"

        rpy="0 0 0" />
      <geometry>
        <mesh
          filename="../meshes/right_upper_wing.STL" />
      </geometry>
      <material
        name="">
        <color
          rgba="0.5 0.5 0.5" />
      </material>
    </visual>
  </link>

  <link
    name="re_ghost_one">
    <inertial>
      <mass
        value="0" />
    </inertial>
  </link>

  <link
    name="re_ghost_two">
    <inertial>
      <mass
        value="0" />
    </inertial>
  </link>

  <link
    name="right_mid_wing">
    <inertial>
      <origin
        xyz="-0.0461463515315643 7.03928811768284E-08 0.0495486671552646"
        rpy="0 0 0" />
      <mass

        value="0.0435482141171194" />
      <inertia
        ixx="5.33772461233864E-05"
        ixy="-1.02931259507254E-10"
        ixz="7.79267317879129E-06"
        iyy="8.30778126011978E-05"

        iyz="5.19612842787995E-12"
        izz="2.9814949368293E-05" />
    </inertial>
    <visual>
      <origin
        xyz="0 0 0"

        rpy="0 0 0" />
      <geometry>
        <mesh

          filename="../meshes/right_mid_wing.STL" />
      </geometry>
      <material
        name="">
        <color
          rgba="0.5 0.5 0.5" />
      </material>
    </visual>
  </link>

  <link
    name="right_hand_wing">
    <inertial>
      <origin
        xyz="-0.0597835085302467 3.75240510469554E-08 0.0458134593577522"
        rpy="0 0 0" />
      <mass
        value="0.0455297796070336" />
      <inertia

        ixx="3.23421498648367E-05"
        ixy="-5.57963540897013E-11"
        ixz="-1.17630180635911E-05"
        iyy="0.000100020749222636"
        iyz="3.58722192723552E-12"
        izz="6.77981793917122E-05" />
    </inertial>
    <visual>
      <origin
        xyz="0 0 0"
        rpy="0 0 0" />
      <geometry>
        <mesh
          filename="../meshes/right_hand_wing.STL" />
      </geometry>
      <material
        name="">
        <color

          rgba="0.5 0.5 0.5" />
      </material>
    </visual>
  </link>















  <joint
    name="tail_joint"
    type="continuous">
    <origin
      xyz="0 -0.0257441763385664 -0.0724066467540735"
      rpy="1.5707963267949 0 0" />
    <parent
      link="torso" />
    <child
      link="tail" />
    <axis
      xyz="-1 0 0" />
    <dynamics
      damping="0.2" />
  </joint>

  <joint
    name="lsr_ghost"
    type="continuous">
    <origin
      xyz="-0.104961900175268 0.117255823661434 -0.0724066467540735"
      rpy="1.5707963267949 0 0" />
    <parent
      link="torso" />
    <child
      link="ls_ghost_one" />
    <axis
      xyz="0 0 -1" />
    <dynamics
      damping="0.2" />
  </joint>

  <joint
    name="lsp_ghost"
    type="continuous">
    <origin
      xyz="0 0 -0.005"
      rpy="0 0 0" />
    <parent
      link="ls_ghost_one" />
    <child
      link="ls_ghost_two" />
    <axis
      xyz="-1 0 0" />
    <dynamics
      damping="0.2" />
  </joint>

  <joint
    name="lsy"
    type="continuous">
    <origin
      xyz="0 -0.00425640192706056 0"
      rpy="0 0 0" />
    <parent
      link="ls_ghost_two" />
    <child
      link="left_upper_wing" />
    <axis
      xyz="0 -1 0" />
    <dynamics
      damping="0.2" />
  </joint>

  <joint
    name="ler_ghost"
    type="continuous">
    <origin
      xyz="-0.0419980875771034 0.00425640192706056 0.0100543231592249"
      rpy="0 0 0" />
    <parent
      link="left_upper_wing" />
    <child
      link="le_ghost_one" />
    <axis
      xyz="0 0 -1" />
    <dynamics
      damping="0.2" />
  </joint>

  <joint
    name="lep_ghost"
    type="continuous">
    <origin
      xyz="0 0 0.005"
      rpy="0 0 0" />
    <parent
      link="le_ghost_one" />
    <child
      link="le_ghost_two" />
    <axis
      xyz="-1 0 0" />
    <dynamics
      damping="0.2" />
  </joint>

  <joint
    name="ley"
    type="continuous">
    <origin
      xyz="0 0 0"
      rpy="0 0 0" />
    <parent
      link="le_ghost_two" />
    <child
      link="left_mid_wing" />
    <axis
      xyz="0 -1 0" />
    <dynamics
      damping="0.2" />
  </joint>

  <joint
    name="lwr"
    type="continuous">
    <origin
      xyz="-0.0929625657844593 0 0"
      rpy="0 0 0" />
    <parent
      link="left_mid_wing" />
    <child
      link="left_hand_wing" />
    <axis
      xyz="0 0 -1" />
    <dynamics
      damping="0.2" />
  </joint>

  <joint
    name="rsr_ghost"
    type="continuous">
    <origin
      xyz="-0.020961900175268 0.117255823661434 -0.0724066467540735"
      rpy="1.5707963267949 0 0" />
    <parent
      link="torso" />
    <child
      link="rs_ghost_one" />
    <axis
      xyz="0 0 -1" />
    <dynamics
      damping="0.2" />
  </joint>

  <joint
    name="rsp_ghost"
    type="continuous">
    <origin
      xyz="0 0 -0.005"
      rpy="0 0 0" />
    <parent
      link="rs_ghost_one" />
    <child
      link="rs_ghost_two" />
    <axis
      xyz="-1 0 0" />
    <dynamics
      damping="0.2" />
  </joint>

  <joint
    name="rsy"
    type="continuous">
    <origin
      xyz="0 -0.00425640192706056 0"
      rpy="0 0 3.14159265358979" />
    <parent
      link="rs_ghost_two" />
    <child
      link="right_upper_wing" />
    <axis
      xyz="0 1 0" />
    <dynamics
      damping="0.2" />
  </joint>

  <joint
    name="rer_ghost"
    type="continuous">
    <origin
      xyz="-0.0419980875771034 -0.00425640192706056 0.0100543231592249"
      rpy="0 0 3.14159265358979" />
    <parent
      link="right_upper_wing" />
    <child
      link="re_ghost_one" />
    <axis
      xyz="0 0 -1" />
    <dynamics
      damping="0.2" />
  </joint>

  <joint
    name="rep_ghost"
    type="continuous">
    <origin
      xyz="0 0 0.005"
      rpy="0 0 0" />
    <parent
      link="re_ghost_one" />
    <child
      link="re_ghost_two" />
    <axis
      xyz="-1 0 0" />
    <dynamics
      damping="0.2" />
  </joint>

  <joint
    name="rey"
    type="continuous">
    <origin
      xyz="0 0 0"
      rpy="0 0 -3.14159265358979" />
    <parent
      link="re_ghost_two" />
    <child
      link="right_mid_wing" />
    <axis
      xyz="0 1 0" />
    <dynamics
      damping="0.2" />
  </joint>

  <joint
    name="rwr"
    type="continuous">
    <origin
      xyz="-0.0929625657844593 0 0"
      rpy="0 0 -3.12250225675825E-15" />
    <parent
      link="right_mid_wing" />
    <child
      link="right_hand_wing" />
    <axis
      xyz="0 0 -1" />
    <dynamics
      damping="0.2" />
  </joint>


</robot>
